Workbook
Name Casing_Collar: 'Casing Review'!$AK$10:$AK$21
Name Casing_Grade: 'Casing Review'!$AL$10:$AL$38
Name Casing_Joint: 'Casing Review'!$AK$10:$AK$21

Sheet Casing Review
A1: Version | B1: =MAX('Rev Hist'!A3:A75) | I1: Minimum Design Factors
I2: Collapse | K2: 1.125
I3: Burst | K3: 1
A4: Company | I4: Tension
A5: Well Name | J5: STC | K5: 1.8
A6: API | J6: LTC | K6: 1.8
D7: KOP Method | E7: N | J7: BTC | K7: 1.6
A8: Casing | D8: Survey Method | E8: y | G8: Set Depth | H8: String # | J8: Premium | K8: 1.5
A9: Frac Gradient | C9: psi/ft | D9: DX | E9: y | F9: DVT | J9: Body Yield | K9: 1.6
A10: STRING 1 | B10: Hole Size | C10: Csg size | D10: Set Depth | E10: Csg Wt | F10: Csg Grade | G10: Csg Collar | H10: Cement Lead Qty | I10: Cement Lead Yield | J10: Cement Tail Qty | K10: Cement Tail Yield | L10: Cement Lead Qty | M10: Cement Lead Yield | N10: Cement Tail Qty | O10: Cement Tail Yield | P10: Cement cu. Ft. | Q10: Cement Height | R10: TOC | S10: MASP | T10: Collapse Strength | U10: Collapse Load | V10: Collapse DF | W10: Burst Strength | X10: Burst Load | Y10: Burst DF | Z10: Tension Strength | AA10: Tension DF | AB10: Neutral Point | AC10: Tension Air | AD10: Tension Buoyed | AE10: ID | AF10: As | AG10: pi | AH10: wL | AI10: Fa | AK10: BTC | AL10: B
C11: A | E11: B | F11: C | G11: I | H11: 1 | J11: 2 | L11: 3 | N11: 4 | AB11: dneutral = dc*(1-ρm/65.4) | AD11: We=W*(1-ρm/65.4) | AF11: As3 | AG11: p3 | AH11: wL3 | AK11: CDC | AL11: C-75
A12: =IF($H$9=1,"Cmt above DVT","") | P12: =$H12*$I12+$J12*$K12+$L12*$M12+$N12*$O12 | Q12: =IF($C12>0,(1/(((((B$20/100)*$B12)+$B12)^2-$C12^2)/183.35))*(P12),0) | R12: =IF($H$9=1,IF(Q12>D$12,"Surface",D12-Q12),IF((Q12+Q14+Q16)>MAX(D$12:D$16),"Surface",MAX(D$12:D$16)-Q16-Q14-Q12)) | S12: =0.05194806*B19*B18-B21*B19 | T12: =DGET('Casing Strengths'!A$7:P$2700,'Casing Strengths'!D$7,C11:G12) | U12: =0.05194806*(B$18-$B$23)*DxSurvey!H57 | V12: =T12/U12 | W12: =DGET('Casing Strengths'!A$7:P$2700,'Casing Strengths'!E7,C11:G12) | X12: =IF(D12=0,0,IF($B$22=0,MAX((0.05194806*$B$18*DxSurvey!H57),MIN($I$24-($B$19-DxSurvey!H57)*$B$36,$L$24-$B$21*($B$19-DxSurvey!H57))),MAX((0.05194806*($B$18-$B$22)*DxSurvey!H57),MIN(($I$24-($B$19-DxSurvey!H57)*$B$36-(0.05194806*$B$22*DxSurvey!H57)),$L$24-$B$21*($B$19-DxSurvey!H57)-(0.05194806*$B$22*DxSurvey!H57))))) | Y12: =W12/X12 | Z12: =DGET('Casing Strengths'!A$7:P$2700,'Casing Strengths'!J7,C11:G12) | AA12: =IF(B17="Y",Z12/AD12,Z12/AC12) | AB12: =DxSurvey!H57*(1-B18/65.4) | AC12: =(AH12+AH14+AH16)/1000 | AD12: =AI12/1000 | AE12: =DGET('Casing Strengths'!A$7:P$2700,'Casing Strengths'!N$7,C11:G12) | AF12: =PI()/4*(C12^2-AE12^2) | AG12: =0.05194806*B18*DxSurvey!H57 | AH12: =E12*DxSurvey!F57 | AI12: =AH12+AH14+AH16-((AG16-AG14)*AF16+(AG14-AG12)*AF14+AG12*AF12) | AK12: DDS | AL12: C-90
C13: A | E13: B | F13: C | G13: I | H13: 5 | J13: 6 | L13: 7 | N13: 8 | P13: =$J12*$K12+$N12*$O12 | Q13: =IF($C12>0,IF(H9=1,MIN(D19-G9,(1/((((($B$20/100)*$B12)+$B12)^2-$C12^2)/183.35))*(P13)),(1/((((($B$20/100)*$B12)+$B12)^2-$C12^2)/183.35))*(P13)),0) | R13: =IF((Q13+Q15+Q17)>MAX(D$12:D$16),"Surface",MAX(D$12:D$16)-Q17-Q15-Q13) | AF13: As2 | AG13: p2 | AH13: wL2 | AK13: DQX | AL13: C-95
A14: =IF(H9=1,"Cmt below DVT","") | P14: =$H14*$I14+$J14*$K14+$L14*$M14+$N14*$O14 | Q14: =IF($C14>0,IF($H$9=1,MIN(D14-D12,(1/(((((B$20/100)*$B14)+$B14)^2-$C14^2)/183.35))*(P14)),(1/(((((B$20/100)*$B14)+$B14)^2-$C14^2)/183.35))*(P14)),0) | T14: =DGET('Casing Strengths'!A$7:P$2700,'Casing Strengths'!D$7,C13:G14) | U14: =0.05194806*(B$18-$B$23)*DxSurvey!H58 | V14: =T14/U14 | W14: =DGET('Casing Strengths'!A$7:P$2700,'Casing Strengths'!E7,C13:G14) | X14: =IF(D14=0,0,IF($B$22=0,MAX((0.05194806*$B$18*DxSurvey!H58),MIN($I$24-($B$19-DxSurvey!H58)*$B$36,$L$24-$B$21*($B$19-DxSurvey!H58))),MAX((0.05194806*($B$18-$B$22)*DxSurvey!H58),MIN(($I$24-($B$19-DxSurvey!H58)*$B$36-(0.05194806*$B$22*DxSurvey!H58)),$L$24-$B$21*($B$19-DxSurvey!H58)-(0.05194806*$B$22*DxSurvey!H58))))) | Y14: =W14/X14 | Z14: =DGET('Casing Strengths'!A$7:P$2700,'Casing Strengths'!J7,C13:G14) | AA14: =IF(B17="Y",Z14/AD14,Z14/AC14) | AB14: =DxSurvey!H58*(1-B18/65.4) | AC14: =(AH14+AH16)/1000 | AD14: =AI14/1000 | AE14: =IF(C14=0,0,DGET('Casing Strengths'!A$7:P$2700,'Casing Strengths'!N$7,C13:G14)) | AF14: =PI()/4*(C14^2-AE14^2) | AG14: =0.05194806*B18*DxSurvey!H58 | AH14: =E14*(DxSurvey!F58-DxSurvey!F57) | AI14: =AH14+AH16-((AG16-AG14)*AF16+AG14*AF14) | AK14: LTC | AL14: H2S-90
C15: A | E15: B | F15: C | G15: I | H15: 9 | J15: 10 | L15: 11 | N15: 12 | P15: =$J14*$K14+$N14*$O14 | Q15: =IF($C14>0,(1/((((($B$20/100)*$B14)+$B14)^2-$C14^2)/183.35))*(P15), 0) | AF15: As1 | AG15: p1 | AH15: wL1 | AK15: PE | AL15: H2S-95
P16: =$H16*$I16+$J16*$K16+$L16*$M16+$N16*$O16 | Q16: =IF($C16>0,(1/(((((B$20/100)*$B16)+$B16)^2-$C16^2)/183.35))*(P16), 0) | T16: =DGET('Casing Strengths'!A$7:P$2700,'Casing Strengths'!D$7,C14:G16) | U16: =0.05194806*(B$18-$B$23)*DxSurvey!H59 | V16: =T16/U16 | W16: =DGET('Casing Strengths'!A$7:P$2700,'Casing Strengths'!E7,C15:G16) | X16: =IF(D16=0,0,IF($B$22=0,MAX((0.05194806*$B$18*DxSurvey!H59),MIN($I$24,$L$24-$B$21*($B$19-DxSurvey!H59))),MAX((0.05194806*($B$18-$B$22)*DxSurvey!H59),MIN(($I$24-(0.05194806*$B$22*DxSurvey!H59)),$L$24-$B$21*($B$19-DxSurvey!H59)-(0.05194806*$B$22*DxSurvey!H59))))) | Y16: =W16/X16 | Z16: =DGET('Casing Strengths'!A$7:P$2700,'Casing Strengths'!J7,C15:G16) | AA16: =IF(B17="Y",Z16/AD16,Z16/AC16) | AB16: =DxSurvey!H59*(1-B18/65.4) | AC16: =(AH16)/1000 | AD16: =AI16/1000 | AE16: =IF(C16=0,0,DGET('Casing Strengths'!A$7:P$2700,'Casing Strengths'!N$7,C15:G16)) | AF16: =PI()/4*(C16^2-AE16^2) | AG16: =0.05194806*B18*DxSurvey!H59 | AH16: =E16*(DxSurvey!F59-DxSurvey!F58) | AI16: =AH16-(AG16*AF16) | AK16: STC | AL16: H-40
A17: Buoyed | P17: =$J16*$K16+$N16*$O16 | Q17: =IF($C16>0,(1/((((($B$20/100)*$B16)+$B16)^2-$C16^2)/183.35))*(P17), 0) | AK17: ST-L | AL17: HCK-55
A18: MW | C18: ppg | AK18: TTRS1 | AL18: HCL-80
A19: TVD | B19: =IF(AND($E$9="y", E$8="Y"),VLOOKUP(MAX(D12:D23),DxSurvey!$B$16:$H$54,7,FALSE),IF(AND(E$9="y",E$7="y"),MAX(DxSurvey!H$57:H$59),MAX($D$12:D$23))) | C19: ft | D19: =MAX(D12:D16) | E19: MD | AE19: =D12/$D$19*AE12+(D14-D12)/$D$19*AE14+(D16-D14)/$D$19*AE16 | AK19: SLIJ-II | AL19: HCN-80
A20: Hole Washout | C20: % | AK20: U-SF | AL20: HCP-110
A21: Internal Gradient | C21: psi/ft | AL21: HCQ-125
A22: Backup Mud | C22: ppg | AL22: I-55
A23: Internal Mud | C23: ppg | AL23: I-80
A24: Next Set Depth | B24: =IF(B34>0,B34,IF(B49>0,B49,IF(B64>0,B64,B79))) | C24: Next MW | D24: =IF(D27>0,B33,B48) | E24: Next BHP | F24: =IF(B34>0,D24*B34*0.05194806,IF(B49>0,D24*B49*0.05194806,IF(B64>0,D24*B64*0.05194806,D24*B79*0.05194806))) | G24: Fracture Initiation Pressure | I24: =B$9*B19 | J24: Max anticipated pressure at shoe | L24: =IF(B34>0,F24-(B34-B19)*B36,IF(B49>0,F39-(B49-B19)*B51,IF(B64>0,F54-(B64-B19)*B66,B19*B18*0.05194806))) | AL24: J-55
A25: STRING 2 | B25: Hole Size | C25: Csg size | D25: Set Depth | E25: Csg Wt | F25: Csg Grade | G25: Csg Collar | H25: Cement Lead Qty | I25: Cement Lead Yield | J25: Cement Tail Qty | K25: Cement Tail Yield | L25: Cement Lead Qty | M25: Cement Lead Yield | N25: Cement Tail Qty | O25: Cement Tail Yield | P25: Cement cu. Ft. | Q25: Cement Height | R25: TOC | S25: MASP | T25: Collapse Strength | U25: Collapse Load | V25: Collapse DF | W25: Burst Strength | X25: Burst Load | Y25: Burst DF | Z25: Tension Strength | AA25: Tension DF | AB25: Neutral Point | AC25: Tension Air | AD25: Tension Buoyed | AE25: ID | AF25: As | AG25: pi | AH25: wL | AI25: Fa | AL25: K-55
C26: A | E26: B | F26: C | G26: I | AF26: As3 | AG26: p3 | AH26: wL3 | AL26: L-80
A27: =IF($H$9=2,"Cmt above DVT","") | P27: =$H27*$I27+$J27*$K27+$L27*$M27+$N27*$O27 | Q27: =IF($C27>0,MIN((1/((((($B$35/100)*$B27)+$B27)^2-$C27^2)/183.35))*(P27),$D$34-$D$19)+MAX(($P27-((((($B$35/100)*$B27)+$B27)^2-$C27^2)/183.35)*($D$34-$D$19))*(1/(($AE$19^2-$C27^2)/183.35)),0), 0) | R27: =IF($H$9=2,IF(Q27>D$27,"Surface",D27-Q27),IF((Q27+Q29+Q31)>MAX(D$27:D$31),"Surface",MAX(D$27:D$31)-Q31-Q29-Q27)) | S27: =0.05194806*B34*B33-B36*B34 | T27: =DGET('Casing Strengths'!A$7:P$2700,'Casing Strengths'!D$7,C26:G27) | U27: =0.05194806*(B$33-$B$38)*DxSurvey!H60 | V27: =T27/U27 | W27: =DGET('Casing Strengths'!A$7:P$2700,'Casing Strengths'!E7,C26:G27) | X27: =IF(D27=0,0,IF($B$37=0,MAX((0.05194806*$B$33*DxSurvey!H60),MIN($I$39,$L$39-$B$36*($B$34-DxSurvey!H60))),MAX((0.05194806*($B$33-$B$37)*DxSurvey!H60),MIN(($I$39-(0.05194806*$B$37*DxSurvey!H60)),$L$39-$B$36*($B$34-DxSurvey!H60)-(0.05194806*$B$37*DxSurvey!H60))))) | Y27: =W27/X27 | Z27: =DGET('Casing Strengths'!A$7:P$2700,'Casing Strengths'!J7,C26:G27) | AA27: =IF(B32="Y",Z27/AD27,Z27/AC27) | AB27: =DxSurvey!H60*(1-B33/65.4) | AC27: =(AH27+AH29+AH31)/1000 | AD27: =AI27/1000 | AE27: =DGET('Casing Strengths'!A$7:P$2700,'Casing Strengths'!N$7,C26:G27) | AF27: =PI()/4*(C27^2-AE27^2) | AG27: =0.05194806*B33*DxSurvey!H60 | AH27: =E27*DxSurvey!F60 | AI27: =AH27+AH29+AH31-((AG31-AG29)*AF31+(AG29-AG27)*AF29+AG27*AF27) | AL27: N-80
C28: A | E28: B | F28: C | G28: I | P28: =$J27*$K27+$N27*$O27 | Q28: =IF($C27>0,(1/((((($B$35/100)*$B27)+$B27)^2-$C27^2)/183.35))*(P28), 0) | R28: =IF((Q28+Q30+Q32)>MAX(D$27:D$31),"Surface",MAX(D$27:D$31)-Q32-Q30-Q28) | AF28: As2 | AG28: p2 | AH28: wL2 | AL28: P-110
A29: =IF($H$9=2,"Cmt below DVT","") | P29: =$H29*$I29+$J29*$K29+$L29*$M29+$N29*$O29 | Q29: =IF($C29>0,IF($H$9=2,MIN(D29-D27,MIN((1/((((($B$35/100)*$B29)+$B29)^2-$C29^2)/183.35))*(P29),$D$34-$D$19)+MAX(($P29-((((($B$35/100)*$B29)+$B29)^2-$C29^2)/183.35)*($D$34-$D$19))*(1/(($AE$19^2-$C29^2)/183.35)),0)),MIN((1/((((($B$35/100)*$B29)+$B29)^2-$C29^2)/183.35))*(P29),$D$34-$D$19)+MAX(($P29-((((($B$35/100)*$B29)+$B29)^2-$C29^2)/183.35)*($D$34-$D$19))*(1/(($AE$19^2-$C29^2)/183.35)),0)),0) | T29: =DGET('Casing Strengths'!A$7:P$2700,'Casing Strengths'!D$7,C28:G29) | U29: =0.05194806*(B$33-$B$38)*DxSurvey!H61 | V29: =T29/U29 | W29: =DGET('Casing Strengths'!A$7:P$2700,'Casing Strengths'!E7,C28:G29) | X29: =IF(D29=0,0,IF($B$37=0,MAX((0.05194806*$B$33*DxSurvey!H61),MIN($I$39,$L$39-$B$36*($B$34-DxSurvey!H61))),MAX((0.05194806*($B$33-$B$37)*DxSurvey!H61),MIN(($I$39-(0.05194806*$B$37*DxSurvey!H61)),$L$39-$B$36*($B$34-DxSurvey!H61)-(0.05194806*$B$37*DxSurvey!H61))))) | Y29: =W29/X29 | Z29: =DGET('Casing Strengths'!A$7:P$2700,'Casing Strengths'!J7,C28:G29) | AA29: =IF(B32="Y",Z29/AD29,Z29/AC29) | AB29: =DxSurvey!H61*(1-B33/65.4) | AC29: =(AH29+AH31)/1000 | AD29: =AI29/1000 | AE29: =IF(C29=0,0,DGET('Casing Strengths'!A$7:P$2700,'Casing Strengths'!N$7,C28:G29)) | AF29: =PI()/4*(C29^2-AE29^2) | AG29: =0.05194806*B33*DxSurvey!H61 | AH29: =E29*(DxSurvey!F61-DxSurvey!F60) | AI29: =AH29+AH31-((AG31-AG29)*AF31+AG29*AF29) | AL29: Q-125
C30: A | E30: B | F30: C | G30: I | P30: =$J29*$K29+$N29*$O29 | Q30: =IF($C29>0,(1/((((($B$35/100)*$B29)+$B29)^2-$C29^2)/183.35))*(P30), 0) | AF30: As1 | AG30: p1 | AH30: wL1 | AL30: S-95
P31: =$H31*$I31+$J31*$K31+$L31*$M31+$N31*$O31 | Q31: =IF($C31>0,MIN((1/((((($B$35/100)*$B31)+$B31)^2-$C31^2)/183.35))*(P31),$D$34-$D$19)+MAX(($P31-((((($B$35/100)*$B31)+$B31)^2-$C31^2)/183.35)*($D$34-$D$19))*(1/(($AE$19^2-$C31^2)/183.35)),0), 0) | T31: =DGET('Casing Strengths'!A$7:P$2700,'Casing Strengths'!D$7,C30:G31) | U31: =0.05194806*(B$33-$B$38)*DxSurvey!H62 | V31: =T31/U31 | W31: =DGET('Casing Strengths'!A$7:P$2700,'Casing Strengths'!E7,C30:G31) | X31: =IF(D31=0,0,IF($B$37=0,MAX((0.05194806*$B$33*DxSurvey!H62),MIN($I$39,$L$39-$B$36*($B$34-DxSurvey!H62))),MAX((0.05194806*($B$33-$B$37)*DxSurvey!H62),MIN(($I$39-(0.05194806*$B$37*DxSurvey!H62)),$L$39-$B$36*($B$34-DxSurvey!H62)-(0.05194806*$B$37*DxSurvey!H62))))) | Y31: =W31/X31 | Z31: =DGET('Casing Strengths'!A$7:P$2700,'Casing Strengths'!J7,C30:G31) | AA31: =IF(B32="Y",Z31/AD31,Z31/AC31) | AB31: =DxSurvey!H62*(1-B33/65.4) | AC31: =(AH31)/1000 | AD31: =AI31/1000 | AE31: =IF(C31=0,0,DGET('Casing Strengths'!A$7:P$2700,'Casing Strengths'!N$7,C30:G31)) | AF31: =PI()/4*(C31^2-AE31^2) | AG31: =0.05194806*B33*DxSurvey!H62 | AH31: =E31*(DxSurvey!F62-DxSurvey!F61) | AI31: =AH31-(AG31*AF31) | AL31: T-95
A32: Buoyed | P32: =$J31*$K31+$N31*$O31 | Q32: =IF($C31>0,(1/((((($B$35/100)*$B31)+$B31)^2-$C31^2)/183.35))*(P32), 0) | AL32: V-150
A33: MW | C33: ppg | AL33: X-52
A34: TVD | B34: =IF(AND($E$9="y", E$8="Y"),VLOOKUP(MAX(D27:D38),DxSurvey!$B$16:$H$54,7,FALSE),IF(AND(E$9="y",E$7="y"),MAX(DxSurvey!H$60:H$62),MAX($D$27:D$31))) | C34: ft | D34: =MAX(D27:D31) | E34: MD | AE34: =D27/$D34*AE27+(D29-D27)/$D34*AE29+(D31-D29)/$D34*AE31 | AL34: X-56
A35: Hole Washout | C35: % | AL35: B
A36: Internal Gradient | C36: psi/ft | AL36: SeAH-70
A37: Backup Mud | C37: ppg | AL37: SeAH-90
A38: Internal Mud | C38: ppg | AL38: SB-80
A39: Next Set Depth | B39: =IF(B49>0,B49,IF(B64>0,B64,IF(B79>0,B79,B94))) | C39: Next MW | D39: =IF(D42>0,B48,B63) | E39: Next BHP | F39: =IF(B49>0,D39*B49*0.05194806,IF(B64>0,D39*B64*0.05194806,IF(B79>0,D39*B79*0.05194806,D39*B104*0.05194806))) | G39: Fracture Initiation Pressure | I39: =B$9*B34 | J39: Max anticipated pressure at shoe | L39: =IF(B49>0,F39-(B49-B34)*B51,IF(B64>0,F54-(B64-B34)*B66,B34*B33*0.05194806))
A40: STRING 3 | B40: Hole Size | C40: Csg size | D40: Set Depth | E40: Csg Wt | F40: Csg Grade | G40: Csg Collar | H40: Cement Lead Qty | I40: Cement Lead Yield | J40: Cement Tail Qty | K40: Cement Tail Yield | L40: Cement Lead Qty | M40: Cement Lead Yield | N40: Cement Tail Qty | O40: Cement Tail Yield | P40: Cement cu. Ft. | Q40: Cement Height | R40: TOC | S40: MASP | T40: Collapse Strength | U40: Collapse Load | V40: Collapse DF | W40: Burst Strength | X40: Burst Load | Y40: Burst DF | Z40: Tension Strength | AA40: Tension DF | AB40: Neutral Point | AC40: Tension Air | AD40: Tension Buoyed | AE40: ID | AF40: As | AG40: pi | AH40: wL | AI40: Fa
...

Sheet Formations
A2: Cell | B2: Formation | C2: Depth (MD)
A3: =J3 | B3: Uinta | C3: 0 | H3: =VLOOKUP(A3,A$3:C$25,2) | J3: =INT(C3/MAX('Casing Review'!$D$19,'Casing Review'!$D$34,'Casing Review'!$D$49,'Casing Review'!$D$64)*37)
A4: =IF(C4=0,"",IF(J4=J5,J4-1,J4)) | B4: Green River | C4: 3135 | H4: =VLOOKUP(A4,A$3:C$25,2) | J4: =INT(C4/MAX('Casing Review'!$D$19,'Casing Review'!$D$34,'Casing Review'!$D$49,'Casing Review'!$D$64)*37)
A5: =IF(C5=0,"",IF(J5=J6,J5-1,J5)) | B5: Garden Gulch | C5: 5854 | H5: =VLOOKUP(A5,A$3:C$25,2) | J5: =INT(C5/MAX('Casing Review'!$D$19,'Casing Review'!$D$34,'Casing Review'!$D$49,'Casing Review'!$D$64)*37)
A6: =IF(C6=0,"",IF(J6=J7,J6-1,J6)) | B6: Uteland Butte | C6: 8238 | H6: =VLOOKUP(A6,A$3:C$25,2) | J6: =INT(C6/MAX('Casing Review'!$D$19,'Casing Review'!$D$34,'Casing Review'!$D$49,'Casing Review'!$D$64)*37)
A7: =IF(C7=0,"",IF(J7=J8,J7-1,J7)) | H7: =VLOOKUP(A7,A$3:C$25,2) | J7: =INT(C7/MAX('Casing Review'!$D$19,'Casing Review'!$D$34,'Casing Review'!$D$49,'Casing Review'!$D$64)*37)
A8: =IF(C8=0,"",IF(J8=J9,J8-1,J8)) | H8: =VLOOKUP(A8,A$3:C$25,2) | J8: =INT(C8/MAX('Casing Review'!$D$19,'Casing Review'!$D$34,'Casing Review'!$D$49,'Casing Review'!$D$64)*37)
A9: =IF(C9=0,"",IF(J9=J10,J9-1,J9)) | H9: =VLOOKUP(A9,A$3:C$25,2) | J9: =INT(C9/MAX('Casing Review'!$D$19,'Casing Review'!$D$34,'Casing Review'!$D$49,'Casing Review'!$D$64)*37)
A10: =IF(C10=0,"",IF(J10=J11,J10-1,J10)) | H10: =VLOOKUP(A10,A$3:C$25,2) | J10: =INT(C10/MAX('Casing Review'!$D$19,'Casing Review'!$D$34,'Casing Review'!$D$49,'Casing Review'!$D$64)*37)
A11: =IF(C11=0,"",IF(J11=J12,J11-1,J11)) | H11: =VLOOKUP(A11,A$3:C$25,2) | J11: =INT(C11/MAX('Casing Review'!$D$19,'Casing Review'!$D$34,'Casing Review'!$D$49,'Casing Review'!$D$64)*37)
A12: =IF(C12=0,"",IF(J12=J13,J12-1,J12)) | H12: =VLOOKUP(A12,A$3:C$25,2) | J12: =INT(C12/MAX('Casing Review'!$D$19,'Casing Review'!$D$34,'Casing Review'!$D$49,'Casing Review'!$D$64)*37)
A13: =IF(C13=0,"",IF(J13=J14,J13-1,J13)) | H13: =VLOOKUP(A13,A$3:C$25,2) | J13: =INT(C13/MAX('Casing Review'!$D$19,'Casing Review'!$D$34,'Casing Review'!$D$49,'Casing Review'!$D$64)*37)
A14: =IF(C14=0,"",IF(J14=J15,J14-1,J14)) | H14: =VLOOKUP(A14,A$3:C$25,2) | J14: =INT(C14/MAX('Casing Review'!$D$19,'Casing Review'!$D$34,'Casing Review'!$D$49,'Casing Review'!$D$64)*37)
A15: =IF(C15=0,"",IF(J15=J16,J15-1,J15)) | H15: =VLOOKUP(A15,A$3:C$25,2) | J15: =INT(C15/MAX('Casing Review'!$D$19,'Casing Review'!$D$34,'Casing Review'!$D$49,'Casing Review'!$D$64)*37)
A16: =IF(C16=0,"",IF(J16=J17,J16-1,J16)) | H16: =VLOOKUP(A16,A$3:C$25,2) | J16: =INT(C16/MAX('Casing Review'!$D$19,'Casing Review'!$D$34,'Casing Review'!$D$49,'Casing Review'!$D$64)*37)
A17: =IF(C17=0,"",IF(J17=J18,J17-1,J17)) | H17: =VLOOKUP(A17,A$3:C$25,2) | J17: =INT(C17/MAX('Casing Review'!$D$19,'Casing Review'!$D$34,'Casing Review'!$D$49,'Casing Review'!$D$64)*37)
A18: =IF(C18=0,"",IF(J18=J19,J18-1,J18)) | H18: =VLOOKUP(A18,A$3:C$25,2) | J18: =INT(C18/MAX('Casing Review'!$D$19,'Casing Review'!$D$34,'Casing Review'!$D$49,'Casing Review'!$D$64)*37)

Sheet DxSurvey
B2: DIRECTIONAL SURVEY CALCULATION
B3: MINIMUM RADIUS OF CURVATURE METHOD
B5: ='Casing Review'!B4 | F5: ='Casing Review'!B5 | I5: ='Casing Review'!B6
D7: N(+)/S(-) | E7: E(+)/W(-) | G7: DxSurvey North Ref | H7: G | I7: (T, M, G) | T7: NS SL ' | U7: =#REF! | V7: =#REF! | W7: EW SL '
A8: K.O. Point | C8: 115.87 | D8: =IF('Casing Review'!$E$9="n", 0,LOOKUP($C8,B$16:B$42,I$16:I$42)) | E8: =IF('Casing Review'!$E$9="n", 0,LOOKUP($C8,B$16:B$42,J$16:J$42)) | G8: Magnetic Declination | I8: (ddd.dd)
A9: Prod. Interval | C9: 8695 | D9: =IF('Casing Review'!$E$9="n", 0,LOOKUP($C9,B$16:B$42,I$16:I$42)) | E9: =IF('Casing Review'!$E$9="n", 0,LOOKUP($C9,B$16:B$42,J$16:J$42)) | G9: Convergence Angle | H9: 0.92 | I9: (ddd.dd) | J9: (Need to determine if survey plats use True or Grid North) | U9: NORTH | V9: EAST
A10: Total Depth | C10: =B44 | D10: =IF('Casing Review'!$E$9="n", 0,LOOKUP($C10,B$16:B$42,I$16:I$42)) | E10: =IF('Casing Review'!$E$9="n", 0,LOOKUP($C10,B$16:B$42,J$16:J$42)) | F10: Proposed Azimuth | H10: 170.89 | U10: SOUTH | V10: WEST
B12: MD | C12: Inclination | D12: Azimuth | E12: Bearing | F12: DOGLEG | G12: F | H12: TVD | I12: N(+)/S(-) | J12: E(+)/W(-) | K12: BH | L12: B-hole | M12: VERT | N12: DOGLEG | O12: TRUE | P12: DELTA N | Q12: DELTA E | R12: Course Lgth | S12: Course Dir | T12: CHART | U12: CHART | V12: CHART | W12: CHART | X12: dx from
F13: ANGLE | I13: Departure | J13: Departure | K13: DEPART | L13: DIR | M13: Section | N13: Severity | O13: DIR | R13: Horz Plane | S13: Horz Plane | T13: VS | U13: TVD | V13: =IF(B47>0,1,2) | W13: =IF(D47>0,1,2) | X13: lease
B14: feet | C14: degrees | D14: degrees | E14: degrees | F14: degrees | G14: factor | H14: feet | I14: feet | J14: feet | K14: feet | L14: degrees | M14: feet | N14: deg/100 ft | O14: degrees | P14: feet | Q14: feet | R14: feet | S14: degrees | T14: feet | U14: feet | V14: feet | W14: feet | X14: line
V15: =MAX(B47:C47) | W15: =MAX(D47:E47)
B16: 0 | C16: 0 | D16: 104 | E16: =IF($H$7="M",D16+$H$8-$H$9,IF( AND($H$7="T",$A$45="g"),D16-$H$9,IF(AND($H$7="g",$A$45="t"),D16+$H$9,D16))) | F16: =IF(C16=C15,0,ACOS(COS(C15*PI()/180)*COS(C16*PI()/180)+(SIN(C15*PI()/180)*SIN(C16*PI()/180))*COS((E16-E15)*PI()/180))*180/PI()) | G16: =IF(F16=0,1,(2/F16)*(180/PI())*TAN(F16*PI()/180/2)) | H16: =H15+(G16*((B16-B15)/2*(COS(C15*PI()/180)+COS(C16*PI()/180)))) | I16: =I15+G16*((B16-B15)/2)*(SIN(C15*PI()/180)*COS(E15*PI()/180)+SIN(C16*PI()/180)*COS(E16*PI()/180)) | J16: =J15+G16*((B16-B15)/2)*(SIN(C15*PI()/180)*SIN(E15*PI()/180)+SIN(C16*PI()/180)*SIN(E16*PI()/180)) | K16: =SQRT(I16^2+J16^2) | L16: =IF(AND(I16=0,J16=0),0,(IF(AND(I16>=0,J16>=0),ATAN(J16/I16)*(180/PI()),IF(AND(I16<0,J16>=0),ATAN(J16/I16)*(180/PI())+180,IF(AND(I16<0,J16<0),ATAN(J16/I16)*(180/PI())+180,ATAN(J16/I16)*(180/PI())+360))))) | M16: =ABS(SQRT(I16^2+J16^2)*(COS(RADIANS(($H$10-IF(I16=0,0,DEGREES(ATAN(J16/I16)))))))) | N16: =IF(B16=B15,0,F16*100/(B16-B15)) | O16: =E16+$F$7 | P16: =G16*((B16-B15)/2)*(SIN(C15*PI()/180)*COS(E15*PI()/180)+SIN(C16*PI()/180)*COS(E16*PI()/180)) | Q16: =G16*((B16-B15)/2)*(SIN(C15*PI()/180)*SIN(E15*PI()/180)+SIN(C16*PI()/180)*SIN(E16*PI()/180)) | R16: =SQRT(P16^2+Q16^2) | S16: =IF(AND(P16=0,Q16=0),0,IF(AND(P16>=0,Q16>=0),ATAN(Q16/P16)*(180/PI()),IF(AND(P16<0,Q16>=0),ATAN(Q16/P16)*(180/PI())+180,IF(AND(P16<0,Q16<0),ATAN(Q16/P16)*(180/PI())+180,ATAN(Q16/P16)*(180/PI())+360)))) | T16: =M16 | U16: =(-H16) | V16: =IF($V$13=1,V$15-I16,V$15+I16) | W16: =IF($W$13=1,W$15-J16,W$15+J16) | X16: =SQRT((W16-$S$186)^2+(V16-$S$186)^2)
A17: ='Casing Review'!D12 | B17: 115.87 | C17: 0 | D17: 104 | E17: =IF($H$7="M",D17+$H$8-$H$9,IF( AND($H$7="T",$A$45="g"),D17-$H$9,IF(AND($H$7="g",$A$45="t"),D17+$H$9,D17))) | F17: =IF(C17=C16,0,ACOS(COS(C16*PI()/180)*COS(C17*PI()/180)+(SIN(C16*PI()/180)*SIN(C17*PI()/180))*COS((E17-E16)*PI()/180))*180/PI()) | G17: =IF(F17=0,1,(2/F17)*(180/PI())*TAN(F17*PI()/180/2)) | H17: =H16+(G17*((B17-B16)/2*(COS(C16*PI()/180)+COS(C17*PI()/180)))) | I17: =I16+G17*((B17-B16)/2)*(SIN(C16*PI()/180)*COS(E16*PI()/180)+SIN(C17*PI()/180)*COS(E17*PI()/180)) | J17: =J16+G17*((B17-B16)/2)*(SIN(C16*PI()/180)*SIN(E16*PI()/180)+SIN(C17*PI()/180)*SIN(E17*PI()/180)) | K17: =SQRT(I17^2+J17^2) | L17: =IF(AND(I17=0,J17=0),0,(IF(AND(I17>=0,J17>=0),ATAN(J17/I17)*(180/PI()),IF(AND(I17<0,J17>=0),ATAN(J17/I17)*(180/PI())+180,IF(AND(I17<0,J17<0),ATAN(J17/I17)*(180/PI())+180,ATAN(J17/I17)*(180/PI())+360))))) | M17: =ABS(SQRT(I17^2+J17^2)*(COS(RADIANS(($H$10-IF(I17=0,0,DEGREES(ATAN(J17/I17)))))))) | N17: =IF(B17=B16,0,F17*100/(B17-B16)) | O17: =E17+$F$7 | P17: =G17*((B17-B16)/2)*(SIN(C16*PI()/180)*COS(E16*PI()/180)+SIN(C17*PI()/180)*COS(E17*PI()/180)) | Q17: =G17*((B17-B16)/2)*(SIN(C16*PI()/180)*SIN(E16*PI()/180)+SIN(C17*PI()/180)*SIN(E17*PI()/180)) | R17: =SQRT(P17^2+Q17^2) | S17: =IF(AND(P17=0,Q17=0),0,IF(AND(P17>=0,Q17>=0),ATAN(Q17/P17)*(180/PI()),IF(AND(P17<0,Q17>=0),ATAN(Q17/P17)*(180/PI())+180,IF(AND(P17<0,Q17<0),ATAN(Q17/P17)*(180/PI())+180,ATAN(Q17/P17)*(180/PI())+360)))) | T17: =M17 | U17: =(-H17) | V17: =IF($V$13=1,V$15-I17,V$15+I17) | W17: =IF($W$13=1,W$15-J17,W$15+J17) | X17: =SQRT((W17-$S$186)^2+(V17-$S$186)^2)
A18: ='Casing Review'!D14 | B18: 500.49 | C18: 5 | D18: 104 | E18: =IF($H$7="M",D18+$H$8-$H$9,IF( AND($H$7="T",$A$45="g"),D18-$H$9,IF(AND($H$7="g",$A$45="t"),D18+$H$9,D18))) | F18: =IF(C18=C17,0,ACOS(COS(C17*PI()/180)*COS(C18*PI()/180)+(SIN(C17*PI()/180)*SIN(C18*PI()/180))*COS((E18-E17)*PI()/180))*180/PI()) | G18: =IF(F18=0,1,(2/F18)*(180/PI())*TAN(F18*PI()/180/2)) | H18: =H17+(G18*((B18-B17)/2*(COS(C17*PI()/180)+COS(C18*PI()/180)))) | I18: =I17+G18*((B18-B17)/2)*(SIN(C17*PI()/180)*COS(E17*PI()/180)+SIN(C18*PI()/180)*COS(E18*PI()/180)) | J18: =J17+G18*((B18-B17)/2)*(SIN(C17*PI()/180)*SIN(E17*PI()/180)+SIN(C18*PI()/180)*SIN(E18*PI()/180)) | K18: =SQRT(I18^2+J18^2) | L18: =IF(AND(I18=0,J18=0),0,(IF(AND(I18>=0,J18>=0),ATAN(J18/I18)*(180/PI()),IF(AND(I18<0,J18>=0),ATAN(J18/I18)*(180/PI())+180,IF(AND(I18<0,J18<0),ATAN(J18/I18)*(180/PI())+180,ATAN(J18/I18)*(180/PI())+360))))) | M18: =ABS(SQRT(I18^2+J18^2)*(COS(RADIANS(($H$10-IF(I18=0,0,DEGREES(ATAN(J18/I18)))))))) | N18: =IF(B18=B17,0,F18*100/(B18-B17)) | O18: =E18+$F$7 | P18: =G18*((B18-B17)/2)*(SIN(C17*PI()/180)*COS(E17*PI()/180)+SIN(C18*PI()/180)*COS(E18*PI()/180)) | Q18: =G18*((B18-B17)/2)*(SIN(C17*PI()/180)*SIN(E17*PI()/180)+SIN(C18*PI()/180)*SIN(E18*PI()/180)) | R18: =SQRT(P18^2+Q18^2) | S18: =IF(AND(P18=0,Q18=0),0,IF(AND(P18>=0,Q18>=0),ATAN(Q18/P18)*(180/PI()),IF(AND(P18<0,Q18>=0),ATAN(Q18/P18)*(180/PI())+180,IF(AND(P18<0,Q18<0),ATAN(Q18/P18)*(180/PI())+180,ATAN(Q18/P18)*(180/PI())+360)))) | T18: =M18 | U18: =(-H18) | V18: =IF($V$13=1,V$15-I18,V$15+I18) | W18: =IF($W$13=1,W$15-J18,W$15+J18) | X18: =SQRT((W18-$S$186)^2+(V18-$S$186)^2)
A19: ='Casing Review'!D16 | B19: 1900 | C19: 5 | D19: 104 | E19: =IF($H$7="M",D19+$H$8-$H$9,IF( AND($H$7="T",$A$45="g"),D19-$H$9,IF(AND($H$7="g",$A$45="t"),D19+$H$9,D19))) | F19: =IF(C19=C18,0,ACOS(COS(C18*PI()/180)*COS(C19*PI()/180)+(SIN(C18*PI()/180)*SIN(C19*PI()/180))*COS((E19-E18)*PI()/180))*180/PI()) | G19: =IF(F19=0,1,(2/F19)*(180/PI())*TAN(F19*PI()/180/2)) | H19: =H18+(G19*((B19-B18)/2*(COS(C18*PI()/180)+COS(C19*PI()/180)))) | I19: =I18+G19*((B19-B18)/2)*(SIN(C18*PI()/180)*COS(E18*PI()/180)+SIN(C19*PI()/180)*COS(E19*PI()/180)) | J19: =J18+G19*((B19-B18)/2)*(SIN(C18*PI()/180)*SIN(E18*PI()/180)+SIN(C19*PI()/180)*SIN(E19*PI()/180)) | K19: =SQRT(I19^2+J19^2) | L19: =IF(AND(I19=0,J19=0),0,(IF(AND(I19>=0,J19>=0),ATAN(J19/I19)*(180/PI()),IF(AND(I19<0,J19>=0),ATAN(J19/I19)*(180/PI())+180,IF(AND(I19<0,J19<0),ATAN(J19/I19)*(180/PI())+180,ATAN(J19/I19)*(180/PI())+360))))) | M19: =ABS(SQRT(I19^2+J19^2)*(COS(RADIANS(($H$10-IF(I19=0,0,DEGREES(ATAN(J19/I19)))))))) | N19: =IF(B19=B18,0,F19*100/(B19-B18)) | O19: =E19+$F$7 | P19: =G19*((B19-B18)/2)*(SIN(C18*PI()/180)*COS(E18*PI()/180)+SIN(C19*PI()/180)*COS(E19*PI()/180)) | Q19: =G19*((B19-B18)/2)*(SIN(C18*PI()/180)*SIN(E18*PI()/180)+SIN(C19*PI()/180)*SIN(E19*PI()/180)) | R19: =SQRT(P19^2+Q19^2) | S19: =IF(AND(P19=0,Q19=0),0,IF(AND(P19>=0,Q19>=0),ATAN(Q19/P19)*(180/PI()),IF(AND(P19<0,Q19>=0),ATAN(Q19/P19)*(180/PI())+180,IF(AND(P19<0,Q19<0),ATAN(Q19/P19)*(180/PI())+180,ATAN(Q19/P19)*(180/PI())+360)))) | T19: =M19 | U19: =(-H19) | V19: =IF($V$13=1,V$15-I19,V$15+I19) | W19: =IF($W$13=1,W$15-J19,W$15+J19) | X19: =SQRT((W19-$S$186)^2+(V19-$S$186)^2)
A20: ='Casing Review'!D27 | B20: 2006.22 | C20: 5 | D20: 104 | E20: =IF($H$7="M",D20+$H$8-$H$9,IF( AND($H$7="T",$A$45="g"),D20-$H$9,IF(AND($H$7="g",$A$45="t"),D20+$H$9,D20))) | F20: =IF(C20=C19,0,ACOS(COS(C19*PI()/180)*COS(C20*PI()/180)+(SIN(C19*PI()/180)*SIN(C20*PI()/180))*COS((E20-E19)*PI()/180))*180/PI()) | G20: =IF(F20=0,1,(2/F20)*(180/PI())*TAN(F20*PI()/180/2)) | H20: =H19+(G20*((B20-B19)/2*(COS(C19*PI()/180)+COS(C20*PI()/180)))) | I20: =I19+G20*((B20-B19)/2)*(SIN(C19*PI()/180)*COS(E19*PI()/180)+SIN(C20*PI()/180)*COS(E20*PI()/180)) | J20: =J19+G20*((B20-B19)/2)*(SIN(C19*PI()/180)*SIN(E19*PI()/180)+SIN(C20*PI()/180)*SIN(E20*PI()/180)) | K20: =SQRT(I20^2+J20^2) | L20: =IF(AND(I20=0,J20=0),0,(IF(AND(I20>=0,J20>=0),ATAN(J20/I20)*(180/PI()),IF(AND(I20<0,J20>=0),ATAN(J20/I20)*(180/PI())+180,IF(AND(I20<0,J20<0),ATAN(J20/I20)*(180/PI())+180,ATAN(J20/I20)*(180/PI())+360))))) | M20: =ABS(SQRT(I20^2+J20^2)*(COS(RADIANS(($H$10-IF(I20=0,0,DEGREES(ATAN(J20/I20)))))))) | N20: =IF(B20=B19,0,F20*100/(B20-B19)) | O20: =E20+$F$7 | P20: =G20*((B20-B19)/2)*(SIN(C19*PI()/180)*COS(E19*PI()/180)+SIN(C20*PI()/180)*COS(E20*PI()/180)) | Q20: =G20*((B20-B19)/2)*(SIN(C19*PI()/180)*SIN(E19*PI()/180)+SIN(C20*PI()/180)*SIN(E20*PI()/180)) | R20: =SQRT(P20^2+Q20^2) | S20: =IF(AND(P20=0,Q20=0),0,IF(AND(P20>=0,Q20>=0),ATAN(Q20/P20)*(180/PI()),IF(AND(P20<0,Q20>=0),ATAN(Q20/P20)*(180/PI())+180,IF(AND(P20<0,Q20<0),ATAN(Q20/P20)*(180/PI())+180,ATAN(Q20/P20)*(180/PI())+360)))) | T20: =M20 | U20: =(-H20) | V20: =IF($V$13=1,V$15-I20,V$15+I20) | W20: =IF($W$13=1,W$15-J20,W$15+J20) | X20: =SQRT((W20-$S$186)^2+(V20-$S$186)^2)
B21: 2786.44 | C21: 12.802 | D21: 104.502 | E21: =IF($H$7="M",D21+$H$8-$H$9,IF( AND($H$7="T",$A$45="g"),D21-$H$9,IF(AND($H$7="g",$A$45="t"),D21+$H$9,D21))) | F21: =IF(C21=C20,0,ACOS(COS(C20*PI()/180)*COS(C21*PI()/180)+(SIN(C20*PI()/180)*SIN(C21*PI()/180))*COS((E21-E20)*PI()/180))*180/PI()) | G21: =IF(F21=0,1,(2/F21)*(180/PI())*TAN(F21*PI()/180/2)) | H21: =H20+(G21*((B21-B20)/2*(COS(C20*PI()/180)+COS(C21*PI()/180)))) | I21: =I20+G21*((B21-B20)/2)*(SIN(C20*PI()/180)*COS(E20*PI()/180)+SIN(C21*PI()/180)*COS(E21*PI()/180)) | J21: =J20+G21*((B21-B20)/2)*(SIN(C20*PI()/180)*SIN(E20*PI()/180)+SIN(C21*PI()/180)*SIN(E21*PI()/180)) | K21: =SQRT(I21^2+J21^2) | L21: =IF(AND(I21=0,J21=0),0,(IF(AND(I21>=0,J21>=0),ATAN(J21/I21)*(180/PI()),IF(AND(I21<0,J21>=0),ATAN(J21/I21)*(180/PI())+180,IF(AND(I21<0,J21<0),ATAN(J21/I21)*(180/PI())+180,ATAN(J21/I21)*(180/PI())+360))))) | M21: =ABS(SQRT(I21^2+J21^2)*(COS(RADIANS(($H$10-IF(I21=0,0,DEGREES(ATAN(J21/I21)))))))) | N21: =IF(B21=B20,0,F21*100/(B21-B20)) | O21: =E21+$F$7 | P21: =G21*((B21-B20)/2)*(SIN(C20*PI()/180)*COS(E20*PI()/180)+SIN(C21*PI()/180)*COS(E21*PI()/180)) | Q21: =G21*((B21-B20)/2)*(SIN(C20*PI()/180)*SIN(E20*PI()/180)+SIN(C21*PI()/180)*SIN(E21*PI()/180)) | R21: =SQRT(P21^2+Q21^2) | S21: =IF(AND(P21=0,Q21=0),0,IF(AND(P21>=0,Q21>=0),ATAN(Q21/P21)*(180/PI()),IF(AND(P21<0,Q21>=0),ATAN(Q21/P21)*(180/PI())+180,IF(AND(P21<0,Q21<0),ATAN(Q21/P21)*(180/PI())+180,ATAN(Q21/P21)*(180/PI())+360)))) | T21: =M21 | U21: =(-H21) | V21: =IF($V$13=1,V$15-I21,V$15+I21) | W21: =IF($W$13=1,W$15-J21,W$15+J21) | X21: =SQRT((W21-$S$186)^2+(V21-$S$186)^2)
B22: 7896 | C22: 12.802 | D22: 104.502 | E22: =IF($H$7="M",D22+$H$8-$H$9,IF( AND($H$7="T",$A$45="g"),D22-$H$9,IF(AND($H$7="g",$A$45="t"),D22+$H$9,D22))) | F22: =IF(C22=C21,0,ACOS(COS(C21*PI()/180)*COS(C22*PI()/180)+(SIN(C21*PI()/180)*SIN(C22*PI()/180))*COS((E22-E21)*PI()/180))*180/PI()) | G22: =IF(F22=0,1,(2/F22)*(180/PI())*TAN(F22*PI()/180/2)) | H22: =H21+(G22*((B22-B21)/2*(COS(C21*PI()/180)+COS(C22*PI()/180)))) | I22: =I21+G22*((B22-B21)/2)*(SIN(C21*PI()/180)*COS(E21*PI()/180)+SIN(C22*PI()/180)*COS(E22*PI()/180)) | J22: =J21+G22*((B22-B21)/2)*(SIN(C21*PI()/180)*SIN(E21*PI()/180)+SIN(C22*PI()/180)*SIN(E22*PI()/180)) | K22: =SQRT(I22^2+J22^2) | L22: =IF(AND(I22=0,J22=0),0,(IF(AND(I22>=0,J22>=0),ATAN(J22/I22)*(180/PI()),IF(AND(I22<0,J22>=0),ATAN(J22/I22)*(180/PI())+180,IF(AND(I22<0,J22<0),ATAN(J22/I22)*(180/PI())+180,ATAN(J22/I22)*(180/PI())+360))))) | M22: =ABS(SQRT(I22^2+J22^2)*(COS(RADIANS(($H$10-IF(I22=0,0,DEGREES(ATAN(J22/I22)))))))) | N22: =IF(B22=B21,0,F22*100/(B22-B21)) | O22: =E22+$F$7 | P22: =G22*((B22-B21)/2)*(SIN(C21*PI()/180)*COS(E21*PI()/180)+SIN(C22*PI()/180)*COS(E22*PI()/180)) | Q22: =G22*((B22-B21)/2)*(SIN(C21*PI()/180)*SIN(E21*PI()/180)+SIN(C22*PI()/180)*SIN(E22*PI()/180)) | R22: =SQRT(P22^2+Q22^2) | S22: =IF(AND(P22=0,Q22=0),0,IF(AND(P22>=0,Q22>=0),ATAN(Q22/P22)*(180/PI()),IF(AND(P22<0,Q22>=0),ATAN(Q22/P22)*(180/PI())+180,IF(AND(P22<0,Q22<0),ATAN(Q22/P22)*(180/PI())+180,ATAN(Q22/P22)*(180/PI())+360)))) | T22: =M22 | U22: =(-H22) | V22: =IF($V$13=1,V$15-I22,V$15+I22) | W22: =IF($W$13=1,W$15-J22,W$15+J22) | X22: =SQRT((W22-$S$186)^2+(V22-$S$186)^2)
B23: 7946.4 | C23: 12.802 | D23: 104.502 | E23: =IF($H$7="M",D23+$H$8-$H$9,IF( AND($H$7="T",$A$45="g"),D23-$H$9,IF(AND($H$7="g",$A$45="t"),D23+$H$9,D23))) | F23: =IF(C23=C22,0,ACOS(COS(C22*PI()/180)*COS(C23*PI()/180)+(SIN(C22*PI()/180)*SIN(C23*PI()/180))*COS((E23-E22)*PI()/180))*180/PI()) | G23: =IF(F23=0,1,(2/F23)*(180/PI())*TAN(F23*PI()/180/2)) | H23: =H22+(G23*((B23-B22)/2*(COS(C22*PI()/180)+COS(C23*PI()/180)))) | I23: =I22+G23*((B23-B22)/2)*(SIN(C22*PI()/180)*COS(E22*PI()/180)+SIN(C23*PI()/180)*COS(E23*PI()/180)) | J23: =J22+G23*((B23-B22)/2)*(SIN(C22*PI()/180)*SIN(E22*PI()/180)+SIN(C23*PI()/180)*SIN(E23*PI()/180)) | K23: =SQRT(I23^2+J23^2) | L23: =IF(AND(I23=0,J23=0),0,(IF(AND(I23>=0,J23>=0),ATAN(J23/I23)*(180/PI()),IF(AND(I23<0,J23>=0),ATAN(J23/I23)*(180/PI())+180,IF(AND(I23<0,J23<0),ATAN(J23/I23)*(180/PI())+180,ATAN(J23/I23)*(180/PI())+360))))) | M23: =ABS(SQRT(I23^2+J23^2)*(COS(RADIANS(($H$10-IF(I23=0,0,DEGREES(ATAN(J23/I23)))))))) | N23: =IF(B23=B22,0,F23*100/(B23-B22)) | O23: =E23+$F$7 | P23: =G23*((B23-B22)/2)*(SIN(C22*PI()/180)*COS(E22*PI()/180)+SIN(C23*PI()/180)*COS(E23*PI()/180)) | Q23: =G23*((B23-B22)/2)*(SIN(C22*PI()/180)*SIN(E22*PI()/180)+SIN(C23*PI()/180)*SIN(E23*PI()/180)) | R23: =SQRT(P23^2+Q23^2) | S23: =IF(AND(P23=0,Q23=0),0,IF(AND(P23>=0,Q23>=0),ATAN(Q23/P23)*(180/PI()),IF(AND(P23<0,Q23>=0),ATAN(Q23/P23)*(180/PI())+180,IF(AND(P23<0,Q23<0),ATAN(Q23/P23)*(180/PI())+180,ATAN(Q23/P23)*(180/PI())+360)))) | T23: =M23 | U23: =(-H23) | V23: =IF($V$13=1,V$15-I23,V$15+I23) | W23: =IF($W$13=1,W$15-J23,W$15+J23) | X23: =SQRT((W23-$S$186)^2+(V23-$S$186)^2)
B24: 8695 | C24: 93.406 | D24: 178.607 | E24: =IF($H$7="M",D24+$H$8-$H$9,IF( AND($H$7="T",$A$45="g"),D24-$H$9,IF(AND($H$7="g",$A$45="t"),D24+$H$9,D24))) | F24: =IF(C24=C23,0,ACOS(COS(C23*PI()/180)*COS(C24*PI()/180)+(SIN(C23*PI()/180)*SIN(C24*PI()/180))*COS((E24-E23)*PI()/180))*180/PI()) | G24: =IF(F24=0,1,(2/F24)*(180/PI())*TAN(F24*PI()/180/2)) | H24: =H23+(G24*((B24-B23)/2*(COS(C23*PI()/180)+COS(C24*PI()/180)))) | I24: =I23+G24*((B24-B23)/2)*(SIN(C23*PI()/180)*COS(E23*PI()/180)+SIN(C24*PI()/180)*COS(E24*PI()/180)) | J24: =J23+G24*((B24-B23)/2)*(SIN(C23*PI()/180)*SIN(E23*PI()/180)+SIN(C24*PI()/180)*SIN(E24*PI()/180)) | K24: =SQRT(I24^2+J24^2) | L24: =IF(AND(I24=0,J24=0),0,(IF(AND(I24>=0,J24>=0),ATAN(J24/I24)*(180/PI()),IF(AND(I24<0,J24>=0),ATAN(J24/I24)*(180/PI())+180,IF(AND(I24<0,J24<0),ATAN(J24/I24)*(180/PI())+180,ATAN(J24/I24)*(180/PI())+360))))) | M24: =ABS(SQRT(I24^2+J24^2)*(COS(RADIANS(($H$10-IF(I24=0,0,DEGREES(ATAN(J24/I24)))))))) | N24: =IF(B24=B23,0,F24*100/(B24-B23)) | O24: =E24+$F$7 | P24: =G24*((B24-B23)/2)*(SIN(C23*PI()/180)*COS(E23*PI()/180)+SIN(C24*PI()/180)*COS(E24*PI()/180)) | Q24: =G24*((B24-B23)/2)*(SIN(C23*PI()/180)*SIN(E23*PI()/180)+SIN(C24*PI()/180)*SIN(E24*PI()/180)) | R24: =SQRT(P24^2+Q24^2) | S24: =IF(AND(P24=0,Q24=0),0,IF(AND(P24>=0,Q24>=0),ATAN(Q24/P24)*(180/PI()),IF(AND(P24<0,Q24>=0),ATAN(Q24/P24)*(180/PI())+180,IF(AND(P24<0,Q24<0),ATAN(Q24/P24)*(180/PI())+180,ATAN(Q24/P24)*(180/PI())+360)))) | T24: =M24 | U24: =(-H24) | V24: =IF($V$13=1,V$15-I24,V$15+I24) | W24: =IF($W$13=1,W$15-J24,W$15+J24) | X24: =SQRT((W24-$S$186)^2+(V24-$S$186)^2)
B25: 18592 | C25: 93.406 | D25: 178.607 | E25: =IF($H$7="M",D25+$H$8-$H$9,IF( AND($H$7="T",$A$45="g"),D25-$H$9,IF(AND($H$7="g",$A$45="t"),D25+$H$9,D25))) | F25: =IF(C25=C24,0,ACOS(COS(C24*PI()/180)*COS(C25*PI()/180)+(SIN(C24*PI()/180)*SIN(C25*PI()/180))*COS((E25-E24)*PI()/180))*180/PI()) | G25: =IF(F25=0,1,(2/F25)*(180/PI())*TAN(F25*PI()/180/2)) | H25: =H24+(G25*((B25-B24)/2*(COS(C24*PI()/180)+COS(C25*PI()/180)))) | I25: =I24+G25*((B25-B24)/2)*(SIN(C24*PI()/180)*COS(E24*PI()/180)+SIN(C25*PI()/180)*COS(E25*PI()/180)) | J25: =J24+G25*((B25-B24)/2)*(SIN(C24*PI()/180)*SIN(E24*PI()/180)+SIN(C25*PI()/180)*SIN(E25*PI()/180)) | K25: =SQRT(I25^2+J25^2) | L25: =IF(AND(I25=0,J25=0),0,(IF(AND(I25>=0,J25>=0),ATAN(J25/I25)*(180/PI()),IF(AND(I25<0,J25>=0),ATAN(J25/I25)*(180/PI())+180,IF(AND(I25<0,J25<0),ATAN(J25/I25)*(180/PI())+180,ATAN(J25/I25)*(180/PI())+360))))) | M25: =ABS(SQRT(I25^2+J25^2)*(COS(RADIANS(($H$10-IF(I25=0,0,DEGREES(ATAN(J25/I25)))))))) | N25: =IF(B25=B24,0,F25*100/(B25-B24)) | O25: =E25+$F$7 | P25: =G25*((B25-B24)/2)*(SIN(C24*PI()/180)*COS(E24*PI()/180)+SIN(C25*PI()/180)*COS(E25*PI()/180)) | Q25: =G25*((B25-B24)/2)*(SIN(C24*PI()/180)*SIN(E24*PI()/180)+SIN(C25*PI()/180)*SIN(E25*PI()/180)) | R25: =SQRT(P25^2+Q25^2) | S25: =IF(AND(P25=0,Q25=0),0,IF(AND(P25>=0,Q25>=0),ATAN(Q25/P25)*(180/PI()),IF(AND(P25<0,Q25>=0),ATAN(Q25/P25)*(180/PI())+180,IF(AND(P25<0,Q25<0),ATAN(Q25/P25)*(180/PI())+180,ATAN(Q25/P25)*(180/PI())+360)))) | T25: =M25 | U25: =(-H25) | V25: =IF($V$13=1,V$15-I25,V$15+I25) | W25: =IF($W$13=1,W$15-J25,W$15+J25) | X25: =SQRT((W25-$S$186)^2+(V25-$S$186)^2)
E26: =IF($H$7="M",D26+$H$8-$H$9,IF( AND($H$7="T",$A$45="g"),D26-$H$9,IF(AND($H$7="g",$A$45="t"),D26+$H$9,D26))) | F26: =IF(C26=C25,0,ACOS(COS(C25*PI()/180)*COS(C26*PI()/180)+(SIN(C25*PI()/180)*SIN(C26*PI()/180))*COS((E26-E25)*PI()/180))*180/PI()) | G26: =IF(F26=0,1,(2/F26)*(180/PI())*TAN(F26*PI()/180/2)) | H26: =H25+(G26*((B26-B25)/2*(COS(C25*PI()/180)+COS(C26*PI()/180)))) | I26: =I25+G26*((B26-B25)/2)*(SIN(C25*PI()/180)*COS(E25*PI()/180)+SIN(C26*PI()/180)*COS(E26*PI()/180)) | J26: =J25+G26*((B26-B25)/2)*(SIN(C25*PI()/180)*SIN(E25*PI()/180)+SIN(C26*PI()/180)*SIN(E26*PI()/180)) | K26: =SQRT(I26^2+J26^2) | L26: =IF(AND(I26=0,J26=0),0,(IF(AND(I26>=0,J26>=0),ATAN(J26/I26)*(180/PI()),IF(AND(I26<0,J26>=0),ATAN(J26/I26)*(180/PI())+180,IF(AND(I26<0,J26<0),ATAN(J26/I26)*(180/PI())+180,ATAN(J26/I26)*(180/PI())+360))))) | M26: =ABS(SQRT(I26^2+J26^2)*(COS(RADIANS(($H$10-IF(I26=0,0,DEGREES(ATAN(J26/I26)))))))) | N26: =IF(B26=B25,0,F26*100/(B26-B25)) | O26: =E26+$F$7 | P26: =G26*((B26-B25)/2)*(SIN(C25*PI()/180)*COS(E25*PI()/180)+SIN(C26*PI()/180)*COS(E26*PI()/180)) | Q26: =G26*((B26-B25)/2)*(SIN(C25*PI()/180)*SIN(E25*PI()/180)+SIN(C26*PI()/180)*SIN(E26*PI()/180)) | R26: =SQRT(P26^2+Q26^2) | S26: =IF(AND(P26=0,Q26=0),0,IF(AND(P26>=0,Q26>=0),ATAN(Q26/P26)*(180/PI()),IF(AND(P26<0,Q26>=0),ATAN(Q26/P26)*(180/PI())+180,IF(AND(P26<0,Q26<0),ATAN(Q26/P26)*(180/PI())+180,ATAN(Q26/P26)*(180/PI())+360)))) | T26: =M26 | U26: =(-H26) | V26: =IF($V$13=1,V$15-I26,V$15+I26) | W26: =IF($W$13=1,W$15-J26,W$15+J26) | X26: =SQRT((W26-$S$186)^2+(V26-$S$186)^2)
E27: =IF($H$7="M",D27+$H$8-$H$9,IF( AND($H$7="T",$A$45="g"),D27-$H$9,IF(AND($H$7="g",$A$45="t"),D27+$H$9,D27))) | F27: =IF(C27=C26,0,ACOS(COS(C26*PI()/180)*COS(C27*PI()/180)+(SIN(C26*PI()/180)*SIN(C27*PI()/180))*COS((E27-E26)*PI()/180))*180/PI()) | G27: =IF(F27=0,1,(2/F27)*(180/PI())*TAN(F27*PI()/180/2)) | H27: =H26+(G27*((B27-B26)/2*(COS(C26*PI()/180)+COS(C27*PI()/180)))) | I27: =I26+G27*((B27-B26)/2)*(SIN(C26*PI()/180)*COS(E26*PI()/180)+SIN(C27*PI()/180)*COS(E27*PI()/180)) | J27: =J26+G27*((B27-B26)/2)*(SIN(C26*PI()/180)*SIN(E26*PI()/180)+SIN(C27*PI()/180)*SIN(E27*PI()/180)) | K27: =SQRT(I27^2+J27^2) | L27: =IF(AND(I27=0,J27=0),0,(IF(AND(I27>=0,J27>=0),ATAN(J27/I27)*(180/PI()),IF(AND(I27<0,J27>=0),ATAN(J27/I27)*(180/PI())+180,IF(AND(I27<0,J27<0),ATAN(J27/I27)*(180/PI())+180,ATAN(J27/I27)*(180/PI())+360))))) | M27: =ABS(SQRT(I27^2+J27^2)*(COS(RADIANS(($H$10-IF(I27=0,0,DEGREES(ATAN(J27/I27)))))))) | N27: =IF(B27=B26,0,F27*100/(B27-B26)) | O27: =E27+$F$7 | P27: =G27*((B27-B26)/2)*(SIN(C26*PI()/180)*COS(E26*PI()/180)+SIN(C27*PI()/180)*COS(E27*PI()/180)) | Q27: =G27*((B27-B26)/2)*(SIN(C26*PI()/180)*SIN(E26*PI()/180)+SIN(C27*PI()/180)*SIN(E27*PI()/180)) | R27: =SQRT(P27^2+Q27^2) | S27: =IF(AND(P27=0,Q27=0),0,IF(AND(P27>=0,Q27>=0),ATAN(Q27/P27)*(180/PI()),IF(AND(P27<0,Q27>=0),ATAN(Q27/P27)*(180/PI())+180,IF(AND(P27<0,Q27<0),ATAN(Q27/P27)*(180/PI())+180,ATAN(Q27/P27)*(180/PI())+360)))) | T27: =M27 | U27: =(-H27) | V27: =IF($V$13=1,V$15-I27,V$15+I27) | W27: =IF($W$13=1,W$15-J27,W$15+J27) | X27: =SQRT((W27-$S$186)^2+(V27-$S$186)^2)
E28: =IF($H$7="M",D28+$H$8-$H$9,IF( AND($H$7="T",$A$45="g"),D28-$H$9,IF(AND($H$7="g",$A$45="t"),D28+$H$9,D28))) | F28: =IF(C28=C27,0,ACOS(COS(C27*PI()/180)*COS(C28*PI()/180)+(SIN(C27*PI()/180)*SIN(C28*PI()/180))*COS((E28-E27)*PI()/180))*180/PI()) | G28: =IF(F28=0,1,(2/F28)*(180/PI())*TAN(F28*PI()/180/2)) | H28: =H27+(G28*((B28-B27)/2*(COS(C27*PI()/180)+COS(C28*PI()/180)))) | I28: =I27+G28*((B28-B27)/2)*(SIN(C27*PI()/180)*COS(E27*PI()/180)+SIN(C28*PI()/180)*COS(E28*PI()/180)) | J28: =J27+G28*((B28-B27)/2)*(SIN(C27*PI()/180)*SIN(E27*PI()/180)+SIN(C28*PI()/180)*SIN(E28*PI()/180)) | K28: =SQRT(I28^2+J28^2) | L28: =IF(AND(I28=0,J28=0),0,(IF(AND(I28>=0,J28>=0),ATAN(J28/I28)*(180/PI()),IF(AND(I28<0,J28>=0),ATAN(J28/I28)*(180/PI())+180,IF(AND(I28<0,J28<0),ATAN(J28/I28)*(180/PI())+180,ATAN(J28/I28)*(180/PI())+360))))) | M28: =ABS(SQRT(I28^2+J28^2)*(COS(RADIANS(($H$10-IF(I28=0,0,DEGREES(ATAN(J28/I28)))))))) | N28: =IF(B28=B27,0,F28*100/(B28-B27)) | O28: =E28+$F$7 | P28: =G28*((B28-B27)/2)*(SIN(C27*PI()/180)*COS(E27*PI()/180)+SIN(C28*PI()/180)*COS(E28*PI()/180)) | Q28: =G28*((B28-B27)/2)*(SIN(C27*PI()/180)*SIN(E27*PI()/180)+SIN(C28*PI()/180)*SIN(E28*PI()/180)) | R28: =SQRT(P28^2+Q28^2) | S28: =IF(AND(P28=0,Q28=0),0,IF(AND(P28>=0,Q28>=0),ATAN(Q28/P28)*(180/PI()),IF(AND(P28<0,Q28>=0),ATAN(Q28/P28)*(180/PI())+180,IF(AND(P28<0,Q28<0),ATAN(Q28/P28)*(180/PI())+180,ATAN(Q28/P28)*(180/PI())+360)))) | T28: =M28 | U28: =(-H28) | V28: =IF($V$13=1,V$15-I28,V$15+I28) | W28: =IF($W$13=1,W$15-J28,W$15+J28) | X28: =SQRT((W28-$S$186)^2+(V28-$S$186)^2)
E29: =IF($H$7="M",D29+$H$8-$H$9,IF( AND($H$7="T",$A$45="g"),D29-$H$9,IF(AND($H$7="g",$A$45="t"),D29+$H$9,D29))) | F29: =IF(C29=C28,0,ACOS(COS(C28*PI()/180)*COS(C29*PI()/180)+(SIN(C28*PI()/180)*SIN(C29*PI()/180))*COS((E29-E28)*PI()/180))*180/PI()) | G29: =IF(F29=0,1,(2/F29)*(180/PI())*TAN(F29*PI()/180/2)) | H29: =H28+(G29*((B29-B28)/2*(COS(C28*PI()/180)+COS(C29*PI()/180)))) | I29: =I28+G29*((B29-B28)/2)*(SIN(C28*PI()/180)*COS(E28*PI()/180)+SIN(C29*PI()/180)*COS(E29*PI()/180)) | J29: =J28+G29*((B29-B28)/2)*(SIN(C28*PI()/180)*SIN(E28*PI()/180)+SIN(C29*PI()/180)*SIN(E29*PI()/180)) | K29: =SQRT(I29^2+J29^2) | L29: =IF(AND(I29=0,J29=0),0,(IF(AND(I29>=0,J29>=0),ATAN(J29/I29)*(180/PI()),IF(AND(I29<0,J29>=0),ATAN(J29/I29)*(180/PI())+180,IF(AND(I29<0,J29<0),ATAN(J29/I29)*(180/PI())+180,ATAN(J29/I29)*(180/PI())+360))))) | M29: =ABS(SQRT(I29^2+J29^2)*(COS(RADIANS(($H$10-IF(I29=0,0,DEGREES(ATAN(J29/I29)))))))) | N29: =IF(B29=B28,0,F29*100/(B29-B28)) | O29: =E29+$F$7 | P29: =G29*((B29-B28)/2)*(SIN(C28*PI()/180)*COS(E28*PI()/180)+SIN(C29*PI()/180)*COS(E29*PI()/180)) | Q29: =G29*((B29-B28)/2)*(SIN(C28*PI()/180)*SIN(E28*PI()/180)+SIN(C29*PI()/180)*SIN(E29*PI()/180)) | R29: =SQRT(P29^2+Q29^2) | S29: =IF(AND(P29=0,Q29=0),0,IF(AND(P29>=0,Q29>=0),ATAN(Q29/P29)*(180/PI()),IF(AND(P29<0,Q29>=0),ATAN(Q29/P29)*(180/PI())+180,IF(AND(P29<0,Q29<0),ATAN(Q29/P29)*(180/PI())+180,ATAN(Q29/P29)*(180/PI())+360)))) | T29: =M29 | U29: =(-H29) | V29: =IF($V$13=1,V$15-I29,V$15+I29) | W29: =IF($W$13=1,W$15-J29,W$15+J29) | X29: =SQRT((W29-$S$186)^2+(V29-$S$186)^2)
A30: ='Casing Review'!D29 | E30: =IF($H$7="M",D30+$H$8-$H$9,IF( AND($H$7="T",$A$45="g"),D30-$H$9,IF(AND($H$7="g",$A$45="t"),D30+$H$9,D30))) | F30: =IF(C30=C29,0,ACOS(COS(C29*PI()/180)*COS(C30*PI()/180)+(SIN(C29*PI()/180)*SIN(C30*PI()/180))*COS((E30-E29)*PI()/180))*180/PI()) | G30: =IF(F30=0,1,(2/F30)*(180/PI())*TAN(F30*PI()/180/2)) | H30: =H29+(G30*((B30-B29)/2*(COS(C29*PI()/180)+COS(C30*PI()/180)))) | I30: =I29+G30*((B30-B29)/2)*(SIN(C29*PI()/180)*COS(E29*PI()/180)+SIN(C30*PI()/180)*COS(E30*PI()/180)) | J30: =J29+G30*((B30-B29)/2)*(SIN(C29*PI()/180)*SIN(E29*PI()/180)+SIN(C30*PI()/180)*SIN(E30*PI()/180)) | K30: =SQRT(I30^2+J30^2) | L30: =IF(AND(I30=0,J30=0),0,(IF(AND(I30>=0,J30>=0),ATAN(J30/I30)*(180/PI()),IF(AND(I30<0,J30>=0),ATAN(J30/I30)*(180/PI())+180,IF(AND(I30<0,J30<0),ATAN(J30/I30)*(180/PI())+180,ATAN(J30/I30)*(180/PI())+360))))) | M30: =ABS(SQRT(I30^2+J30^2)*(COS(RADIANS(($H$10-IF(I30=0,0,DEGREES(ATAN(J30/I30)))))))) | N30: =IF(B30=B29,0,F30*100/(B30-B29)) | O30: =E30+$F$7 | P30: =G30*((B30-B29)/2)*(SIN(C29*PI()/180)*COS(E29*PI()/180)+SIN(C30*PI()/180)*COS(E30*PI()/180)) | Q30: =G30*((B30-B29)/2)*(SIN(C29*PI()/180)*SIN(E29*PI()/180)+SIN(C30*PI()/180)*SIN(E30*PI()/180)) | R30: =SQRT(P30^2+Q30^2) | S30: =IF(AND(P30=0,Q30=0),0,IF(AND(P30>=0,Q30>=0),ATAN(Q30/P30)*(180/PI()),IF(AND(P30<0,Q30>=0),ATAN(Q30/P30)*(180/PI())+180,IF(AND(P30<0,Q30<0),ATAN(Q30/P30)*(180/PI())+180,ATAN(Q30/P30)*(180/PI())+360)))) | T30: =M30 | U30: =(-H30) | V30: =IF($V$13=1,V$15-I30,V$15+I30) | W30: =IF($W$13=1,W$15-J30,W$15+J30) | X30: =SQRT((W30-$S$186)^2+(V30-$S$186)^2)
A31: ='Casing Review'!D31 | E31: =IF($H$7="M",D31+$H$8-$H$9,IF( AND($H$7="T",$A$45="g"),D31-$H$9,IF(AND($H$7="g",$A$45="t"),D31+$H$9,D31))) | F31: =IF(C31=C30,0,ACOS(COS(C30*PI()/180)*COS(C31*PI()/180)+(SIN(C30*PI()/180)*SIN(C31*PI()/180))*COS((E31-E30)*PI()/180))*180/PI()) | G31: =IF(F31=0,1,(2/F31)*(180/PI())*TAN(F31*PI()/180/2)) | H31: =H30+(G31*((B31-B30)/2*(COS(C30*PI()/180)+COS(C31*PI()/180)))) | I31: =I30+G31*((B31-B30)/2)*(SIN(C30*PI()/180)*COS(E30*PI()/180)+SIN(C31*PI()/180)*COS(E31*PI()/180)) | J31: =J30+G31*((B31-B30)/2)*(SIN(C30*PI()/180)*SIN(E30*PI()/180)+SIN(C31*PI()/180)*SIN(E31*PI()/180)) | K31: =SQRT(I31^2+J31^2) | L31: =IF(AND(I31=0,J31=0),0,(IF(AND(I31>=0,J31>=0),ATAN(J31/I31)*(180/PI()),IF(AND(I31<0,J31>=0),ATAN(J31/I31)*(180/PI())+180,IF(AND(I31<0,J31<0),ATAN(J31/I31)*(180/PI())+180,ATAN(J31/I31)*(180/PI())+360))))) | M31: =ABS(SQRT(I31^2+J31^2)*(COS(RADIANS(($H$10-IF(I31=0,0,DEGREES(ATAN(J31/I31)))))))) | N31: =IF(B31=B30,0,F31*100/(B31-B30)) | O31: =E31+$F$7 | P31: =G31*((B31-B30)/2)*(SIN(C30*PI()/180)*COS(E30*PI()/180)+SIN(C31*PI()/180)*COS(E31*PI()/180)) | Q31: =G31*((B31-B30)/2)*(SIN(C30*PI()/180)*SIN(E30*PI()/180)+SIN(C31*PI()/180)*SIN(E31*PI()/180)) | R31: =SQRT(P31^2+Q31^2) | S31: =IF(AND(P31=0,Q31=0),0,IF(AND(P31>=0,Q31>=0),ATAN(Q31/P31)*(180/PI()),IF(AND(P31<0,Q31>=0),ATAN(Q31/P31)*(180/PI())+180,IF(AND(P31<0,Q31<0),ATAN(Q31/P31)*(180/PI())+180,ATAN(Q31/P31)*(180/PI())+360)))) | T31: =M31 | U31: =(-H31) | V31: =IF($V$13=1,V$15-I31,V$15+I31) | W31: =IF($W$13=1,W$15-J31,W$15+J31) | X31: =SQRT((W31-$S$186)^2+(V31-$S$186)^2)
A32: ='Casing Review'!D42 | E32: =IF($H$7="M",D32+$H$8-$H$9,IF( AND($H$7="T",$A$45="g"),D32-$H$9,IF(AND($H$7="g",$A$45="t"),D32+$H$9,D32))) | F32: =IF(C32=C31,0,ACOS(COS(C31*PI()/180)*COS(C32*PI()/180)+(SIN(C31*PI()/180)*SIN(C32*PI()/180))*COS((E32-E31)*PI()/180))*180/PI()) | G32: =IF(F32=0,1,(2/F32)*(180/PI())*TAN(F32*PI()/180/2)) | H32: =H31+(G32*((B32-B31)/2*(COS(C31*PI()/180)+COS(C32*PI()/180)))) | I32: =I31+G32*((B32-B31)/2)*(SIN(C31*PI()/180)*COS(E31*PI()/180)+SIN(C32*PI()/180)*COS(E32*PI()/180)) | J32: =J31+G32*((B32-B31)/2)*(SIN(C31*PI()/180)*SIN(E31*PI()/180)+SIN(C32*PI()/180)*SIN(E32*PI()/180)) | K32: =SQRT(I32^2+J32^2) | L32: =IF(AND(I32=0,J32=0),0,(IF(AND(I32>=0,J32>=0),ATAN(J32/I32)*(180/PI()),IF(AND(I32<0,J32>=0),ATAN(J32/I32)*(180/PI())+180,IF(AND(I32<0,J32<0),ATAN(J32/I32)*(180/PI())+180,ATAN(J32/I32)*(180/PI())+360))))) | M32: =ABS(SQRT(I32^2+J32^2)*(COS(RADIANS(($H$10-IF(I32=0,0,DEGREES(ATAN(J32/I32)))))))) | N32: =IF(B32=B31,0,F32*100/(B32-B31)) | O32: =E32+$F$7 | P32: =G32*((B32-B31)/2)*(SIN(C31*PI()/180)*COS(E31*PI()/180)+SIN(C32*PI()/180)*COS(E32*PI()/180)) | Q32: =G32*((B32-B31)/2)*(SIN(C31*PI()/180)*SIN(E31*PI()/180)+SIN(C32*PI()/180)*SIN(E32*PI()/180)) | R32: =SQRT(P32^2+Q32^2) | S32: =IF(AND(P32=0,Q32=0),0,IF(AND(P32>=0,Q32>=0),ATAN(Q32/P32)*(180/PI()),IF(AND(P32<0,Q32>=0),ATAN(Q32/P32)*(180/PI())+180,IF(AND(P32<0,Q32<0),ATAN(Q32/P32)*(180/PI())+180,ATAN(Q32/P32)*(180/PI())+360)))) | T32: =M32 | U32: =(-H32) | V32: =IF($V$13=1,V$15-I32,V$15+I32) | W32: =IF($W$13=1,W$15-J32,W$15+J32) | X32: =SQRT((W32-$S$186)^2+(V32-$S$186)^2)
E33: =IF($H$7="M",D33+$H$8-$H$9,IF( AND($H$7="T",$A$45="g"),D33-$H$9,IF(AND($H$7="g",$A$45="t"),D33+$H$9,D33))) | F33: =IF(C33=C32,0,ACOS(COS(C32*PI()/180)*COS(C33*PI()/180)+(SIN(C32*PI()/180)*SIN(C33*PI()/180))*COS((E33-E32)*PI()/180))*180/PI()) | G33: =IF(F33=0,1,(2/F33)*(180/PI())*TAN(F33*PI()/180/2)) | H33: =H32+(G33*((B33-B32)/2*(COS(C32*PI()/180)+COS(C33*PI()/180)))) | I33: =I32+G33*((B33-B32)/2)*(SIN(C32*PI()/180)*COS(E32*PI()/180)+SIN(C33*PI()/180)*COS(E33*PI()/180)) | J33: =J32+G33*((B33-B32)/2)*(SIN(C32*PI()/180)*SIN(E32*PI()/180)+SIN(C33*PI()/180)*SIN(E33*PI()/180)) | K33: =SQRT(I33^2+J33^2) | L33: =IF(AND(I33=0,J33=0),0,(IF(AND(I33>=0,J33>=0),ATAN(J33/I33)*(180/PI()),IF(AND(I33<0,J33>=0),ATAN(J33/I33)*(180/PI())+180,IF(AND(I33<0,J33<0),ATAN(J33/I33)*(180/PI())+180,ATAN(J33/I33)*(180/PI())+360))))) | M33: =ABS(SQRT(I33^2+J33^2)*(COS(RADIANS(($H$10-IF(I33=0,0,DEGREES(ATAN(J33/I33)))))))) | N33: =IF(B33=B32,0,F33*100/(B33-B32)) | O33: =E33+$F$7 | P33: =G33*((B33-B32)/2)*(SIN(C32*PI()/180)*COS(E32*PI()/180)+SIN(C33*PI()/180)*COS(E33*PI()/180)) | Q33: =G33*((B33-B32)/2)*(SIN(C32*PI()/180)*SIN(E32*PI()/180)+SIN(C33*PI()/180)*SIN(E33*PI()/180)) | R33: =SQRT(P33^2+Q33^2) | S33: =IF(AND(P33=0,Q33=0),0,IF(AND(P33>=0,Q33>=0),ATAN(Q33/P33)*(180/PI()),IF(AND(P33<0,Q33>=0),ATAN(Q33/P33)*(180/PI())+180,IF(AND(P33<0,Q33<0),ATAN(Q33/P33)*(180/PI())+180,ATAN(Q33/P33)*(180/PI())+360)))) | T33: =M33 | U33: =(-H33) | V33: =IF($V$13=1,V$15-I33,V$15+I33) | W33: =IF($W$13=1,W$15-J33,W$15+J33) | X33: =SQRT((W33-$S$186)^2+(V33-$S$186)^2)
A34: ='Casing Review'!D44 | E34: =IF($H$7="M",D34+$H$8-$H$9,IF( AND($H$7="T",$A$45="g"),D34-$H$9,IF(AND($H$7="g",$A$45="t"),D34+$H$9,D34))) | F34: =IF(C34=C33,0,ACOS(COS(C33*PI()/180)*COS(C34*PI()/180)+(SIN(C33*PI()/180)*SIN(C34*PI()/180))*COS((E34-E33)*PI()/180))*180/PI()) | G34: =IF(F34=0,1,(2/F34)*(180/PI())*TAN(F34*PI()/180/2)) | H34: =H33+(G34*((B34-B33)/2*(COS(C33*PI()/180)+COS(C34*PI()/180)))) | I34: =I33+G34*((B34-B33)/2)*(SIN(C33*PI()/180)*COS(E33*PI()/180)+SIN(C34*PI()/180)*COS(E34*PI()/180)) | J34: =J33+G34*((B34-B33)/2)*(SIN(C33*PI()/180)*SIN(E33*PI()/180)+SIN(C34*PI()/180)*SIN(E34*PI()/180)) | K34: =SQRT(I34^2+J34^2) | L34: =IF(AND(I34=0,J34=0),0,(IF(AND(I34>=0,J34>=0),ATAN(J34/I34)*(180/PI()),IF(AND(I34<0,J34>=0),ATAN(J34/I34)*(180/PI())+180,IF(AND(I34<0,J34<0),ATAN(J34/I34)*(180/PI())+180,ATAN(J34/I34)*(180/PI())+360))))) | M34: =ABS(SQRT(I34^2+J34^2)*(COS(RADIANS(($H$10-IF(I34=0,0,DEGREES(ATAN(J34/I34)))))))) | N34: =IF(B34=B33,0,F34*100/(B34-B33)) | O34: =E34+$F$7 | P34: =G34*((B34-B33)/2)*(SIN(C33*PI()/180)*COS(E33*PI()/180)+SIN(C34*PI()/180)*COS(E34*PI()/180)) | Q34: =G34*((B34-B33)/2)*(SIN(C33*PI()/180)*SIN(E33*PI()/180)+SIN(C34*PI()/180)*SIN(E34*PI()/180)) | R34: =SQRT(P34^2+Q34^2) | S34: =IF(AND(P34=0,Q34=0),0,IF(AND(P34>=0,Q34>=0),ATAN(Q34/P34)*(180/PI()),IF(AND(P34<0,Q34>=0),ATAN(Q34/P34)*(180/PI())+180,IF(AND(P34<0,Q34<0),ATAN(Q34/P34)*(180/PI())+180,ATAN(Q34/P34)*(180/PI())+360)))) | T34: =M34 | U34: =(-H34) | V34: =IF($V$13=1,V$15-I34,V$15+I34) | W34: =IF($W$13=1,W$15-J34,W$15+J34) | X34: =SQRT((W34-$S$186)^2+(V34-$S$186)^2)
A35: ='Casing Review'!D46 | E35: =IF($H$7="M",D35+$H$8-$H$9,IF( AND($H$7="T",$A$45="g"),D35-$H$9,IF(AND($H$7="g",$A$45="t"),D35+$H$9,D35))) | F35: =IF(C35=C34,0,ACOS(COS(C34*PI()/180)*COS(C35*PI()/180)+(SIN(C34*PI()/180)*SIN(C35*PI()/180))*COS((E35-E34)*PI()/180))*180/PI()) | G35: =IF(F35=0,1,(2/F35)*(180/PI())*TAN(F35*PI()/180/2)) | H35: =H34+(G35*((B35-B34)/2*(COS(C34*PI()/180)+COS(C35*PI()/180)))) | I35: =I34+G35*((B35-B34)/2)*(SIN(C34*PI()/180)*COS(E34*PI()/180)+SIN(C35*PI()/180)*COS(E35*PI()/180)) | J35: =J34+G35*((B35-B34)/2)*(SIN(C34*PI()/180)*SIN(E34*PI()/180)+SIN(C35*PI()/180)*SIN(E35*PI()/180)) | K35: =SQRT(I35^2+J35^2) | L35: =IF(AND(I35=0,J35=0),0,(IF(AND(I35>=0,J35>=0),ATAN(J35/I35)*(180/PI()),IF(AND(I35<0,J35>=0),ATAN(J35/I35)*(180/PI())+180,IF(AND(I35<0,J35<0),ATAN(J35/I35)*(180/PI())+180,ATAN(J35/I35)*(180/PI())+360))))) | M35: =ABS(SQRT(I35^2+J35^2)*(COS(RADIANS(($H$10-IF(I35=0,0,DEGREES(ATAN(J35/I35)))))))) | N35: =IF(B35=B34,0,F35*100/(B35-B34)) | O35: =E35+$F$7 | P35: =G35*((B35-B34)/2)*(SIN(C34*PI()/180)*COS(E34*PI()/180)+SIN(C35*PI()/180)*COS(E35*PI()/180)) | Q35: =G35*((B35-B34)/2)*(SIN(C34*PI()/180)*SIN(E34*PI()/180)+SIN(C35*PI()/180)*SIN(E35*PI()/180)) | R35: =SQRT(P35^2+Q35^2) | S35: =IF(AND(P35=0,Q35=0),0,IF(AND(P35>=0,Q35>=0),ATAN(Q35/P35)*(180/PI()),IF(AND(P35<0,Q35>=0),ATAN(Q35/P35)*(180/PI())+180,IF(AND(P35<0,Q35<0),ATAN(Q35/P35)*(180/PI())+180,ATAN(Q35/P35)*(180/PI())+360)))) | T35: =M35 | U35: =(-H35) | V35: =IF($V$13=1,V$15-I35,V$15+I35) | W35: =IF($W$13=1,W$15-J35,W$15+J35) | X35: =SQRT((W35-$S$186)^2+(V35-$S$186)^2)
A36: ='Casing Review'!B69 | E36: =IF($H$7="M",D36+$H$8-$H$9,IF( AND($H$7="T",$A$45="g"),D36-$H$9,IF(AND($H$7="g",$A$45="t"),D36+$H$9,D36))) | F36: =IF(C36=C35,0,ACOS(COS(C35*PI()/180)*COS(C36*PI()/180)+(SIN(C35*PI()/180)*SIN(C36*PI()/180))*COS((E36-E35)*PI()/180))*180/PI()) | G36: =IF(F36=0,1,(2/F36)*(180/PI())*TAN(F36*PI()/180/2)) | H36: =H35+(G36*((B36-B35)/2*(COS(C35*PI()/180)+COS(C36*PI()/180)))) | I36: =I35+G36*((B36-B35)/2)*(SIN(C35*PI()/180)*COS(E35*PI()/180)+SIN(C36*PI()/180)*COS(E36*PI()/180)) | J36: =J35+G36*((B36-B35)/2)*(SIN(C35*PI()/180)*SIN(E35*PI()/180)+SIN(C36*PI()/180)*SIN(E36*PI()/180)) | K36: =SQRT(I36^2+J36^2) | L36: =IF(AND(I36=0,J36=0),0,(IF(AND(I36>=0,J36>=0),ATAN(J36/I36)*(180/PI()),IF(AND(I36<0,J36>=0),ATAN(J36/I36)*(180/PI())+180,IF(AND(I36<0,J36<0),ATAN(J36/I36)*(180/PI())+180,ATAN(J36/I36)*(180/PI())+360))))) | M36: =ABS(SQRT(I36^2+J36^2)*(COS(RADIANS(($H$10-IF(I36=0,0,DEGREES(ATAN(J36/I36)))))))) | N36: =IF(B36=B35,0,F36*100/(B36-B35)) | O36: =E36+$F$7 | P36: =G36*((B36-B35)/2)*(SIN(C35*PI()/180)*COS(E35*PI()/180)+SIN(C36*PI()/180)*COS(E36*PI()/180)) | Q36: =G36*((B36-B35)/2)*(SIN(C35*PI()/180)*SIN(E35*PI()/180)+SIN(C36*PI()/180)*SIN(E36*PI()/180)) | R36: =SQRT(P36^2+Q36^2) | S36: =IF(AND(P36=0,Q36=0),0,IF(AND(P36>=0,Q36>=0),ATAN(Q36/P36)*(180/PI()),IF(AND(P36<0,Q36>=0),ATAN(Q36/P36)*(180/PI())+180,IF(AND(P36<0,Q36<0),ATAN(Q36/P36)*(180/PI())+180,ATAN(Q36/P36)*(180/PI())+360)))) | T36: =M36 | U36: =(-H36) | V36: =IF($V$13=1,V$15-I36,V$15+I36) | W36: =IF($W$13=1,W$15-J36,W$15+J36) | X36: =SQRT((W36-$S$186)^2+(V36-$S$186)^2)
A37: ='Casing Review'!D57 | E37: =IF($H$7="M",D37+$H$8-$H$9,IF( AND($H$7="T",$A$45="g"),D37-$H$9,IF(AND($H$7="g",$A$45="t"),D37+$H$9,D37))) | F37: =IF(C37=C36,0,ACOS(COS(C36*PI()/180)*COS(C37*PI()/180)+(SIN(C36*PI()/180)*SIN(C37*PI()/180))*COS((E37-E36)*PI()/180))*180/PI()) | G37: =IF(F37=0,1,(2/F37)*(180/PI())*TAN(F37*PI()/180/2)) | H37: =H36+(G37*((B37-B36)/2*(COS(C36*PI()/180)+COS(C37*PI()/180)))) | I37: =I36+G37*((B37-B36)/2)*(SIN(C36*PI()/180)*COS(E36*PI()/180)+SIN(C37*PI()/180)*COS(E37*PI()/180)) | J37: =J36+G37*((B37-B36)/2)*(SIN(C36*PI()/180)*SIN(E36*PI()/180)+SIN(C37*PI()/180)*SIN(E37*PI()/180)) | K37: =SQRT(I37^2+J37^2) | L37: =IF(AND(I37=0,J37=0),0,(IF(AND(I37>=0,J37>=0),ATAN(J37/I37)*(180/PI()),IF(AND(I37<0,J37>=0),ATAN(J37/I37)*(180/PI())+180,IF(AND(I37<0,J37<0),ATAN(J37/I37)*(180/PI())+180,ATAN(J37/I37)*(180/PI())+360))))) | M37: =ABS(SQRT(I37^2+J37^2)*(COS(RADIANS(($H$10-IF(I37=0,0,DEGREES(ATAN(J37/I37)))))))) | N37: =IF(B37=B36,0,F37*100/(B37-B36)) | O37: =E37+$F$7 | P37: =G37*((B37-B36)/2)*(SIN(C36*PI()/180)*COS(E36*PI()/180)+SIN(C37*PI()/180)*COS(E37*PI()/180)) | Q37: =G37*((B37-B36)/2)*(SIN(C36*PI()/180)*SIN(E36*PI()/180)+SIN(C37*PI()/180)*SIN(E37*PI()/180)) | R37: =SQRT(P37^2+Q37^2) | S37: =IF(AND(P37=0,Q37=0),0,IF(AND(P37>=0,Q37>=0),ATAN(Q37/P37)*(180/PI()),IF(AND(P37<0,Q37>=0),ATAN(Q37/P37)*(180/PI())+180,IF(AND(P37<0,Q37<0),ATAN(Q37/P37)*(180/PI())+180,ATAN(Q37/P37)*(180/PI())+360)))) | T37: =M37 | U37: =(-H37) | V37: =IF($V$13=1,V$15-I37,V$15+I37) | W37: =IF($W$13=1,W$15-J37,W$15+J37) | X37: =SQRT((W37-$S$186)^2+(V37-$S$186)^2)
A38: ='Casing Review'!D59 | E38: =IF($H$7="M",D38+$H$8-$H$9,IF( AND($H$7="T",$A$45="g"),D38-$H$9,IF(AND($H$7="g",$A$45="t"),D38+$H$9,D38))) | F38: =IF(C38=C37,0,ACOS(COS(C37*PI()/180)*COS(C38*PI()/180)+(SIN(C37*PI()/180)*SIN(C38*PI()/180))*COS((E38-E37)*PI()/180))*180/PI()) | G38: =IF(F38=0,1,(2/F38)*(180/PI())*TAN(F38*PI()/180/2)) | H38: =H37+(G38*((B38-B37)/2*(COS(C37*PI()/180)+COS(C38*PI()/180)))) | I38: =I37+G38*((B38-B37)/2)*(SIN(C37*PI()/180)*COS(E37*PI()/180)+SIN(C38*PI()/180)*COS(E38*PI()/180)) | J38: =J37+G38*((B38-B37)/2)*(SIN(C37*PI()/180)*SIN(E37*PI()/180)+SIN(C38*PI()/180)*SIN(E38*PI()/180)) | K38: =SQRT(I38^2+J38^2) | L38: =IF(AND(I38=0,J38=0),0,(IF(AND(I38>=0,J38>=0),ATAN(J38/I38)*(180/PI()),IF(AND(I38<0,J38>=0),ATAN(J38/I38)*(180/PI())+180,IF(AND(I38<0,J38<0),ATAN(J38/I38)*(180/PI())+180,ATAN(J38/I38)*(180/PI())+360))))) | M38: =ABS(SQRT(I38^2+J38^2)*(COS(RADIANS(($H$10-IF(I38=0,0,DEGREES(ATAN(J38/I38)))))))) | N38: =IF(B38=B37,0,F38*100/(B38-B37)) | O38: =E38+$F$7 | P38: =G38*((B38-B37)/2)*(SIN(C37*PI()/180)*COS(E37*PI()/180)+SIN(C38*PI()/180)*COS(E38*PI()/180)) | Q38: =G38*((B38-B37)/2)*(SIN(C37*PI()/180)*SIN(E37*PI()/180)+SIN(C38*PI()/180)*SIN(E38*PI()/180)) | R38: =SQRT(P38^2+Q38^2) | S38: =IF(AND(P38=0,Q38=0),0,IF(AND(P38>=0,Q38>=0),ATAN(Q38/P38)*(180/PI()),IF(AND(P38<0,Q38>=0),ATAN(Q38/P38)*(180/PI())+180,IF(AND(P38<0,Q38<0),ATAN(Q38/P38)*(180/PI())+180,ATAN(Q38/P38)*(180/PI())+360)))) | T38: =M38 | U38: =(-H38) | V38: =IF($V$13=1,V$15-I38,V$15+I38) | W38: =IF($W$13=1,W$15-J38,W$15+J38) | X38: =SQRT((W38-$S$186)^2+(V38-$S$186)^2)
A39: ='Casing Review'!D61 | E39: =IF($H$7="M",D39+$H$8-$H$9,IF( AND($H$7="T",$A$45="g"),D39-$H$9,IF(AND($H$7="g",$A$45="t"),D39+$H$9,D39))) | F39: =IF(C39=C38,0,ACOS(COS(C38*PI()/180)*COS(C39*PI()/180)+(SIN(C38*PI()/180)*SIN(C39*PI()/180))*COS((E39-E38)*PI()/180))*180/PI()) | G39: =IF(F39=0,1,(2/F39)*(180/PI())*TAN(F39*PI()/180/2)) | H39: =H38+(G39*((B39-B38)/2*(COS(C38*PI()/180)+COS(C39*PI()/180)))) | I39: =I38+G39*((B39-B38)/2)*(SIN(C38*PI()/180)*COS(E38*PI()/180)+SIN(C39*PI()/180)*COS(E39*PI()/180)) | J39: =J38+G39*((B39-B38)/2)*(SIN(C38*PI()/180)*SIN(E38*PI()/180)+SIN(C39*PI()/180)*SIN(E39*PI()/180)) | K39: =SQRT(I39^2+J39^2) | L39: =IF(AND(I39=0,J39=0),0,(IF(AND(I39>=0,J39>=0),ATAN(J39/I39)*(180/PI()),IF(AND(I39<0,J39>=0),ATAN(J39/I39)*(180/PI())+180,IF(AND(I39<0,J39<0),ATAN(J39/I39)*(180/PI())+180,ATAN(J39/I39)*(180/PI())+360))))) | M39: =ABS(SQRT(I39^2+J39^2)*(COS(RADIANS(($H$10-IF(I39=0,0,DEGREES(ATAN(J39/I39)))))))) | N39: =IF(B39=B38,0,F39*100/(B39-B38)) | O39: =E39+$F$7 | P39: =G39*((B39-B38)/2)*(SIN(C38*PI()/180)*COS(E38*PI()/180)+SIN(C39*PI()/180)*COS(E39*PI()/180)) | Q39: =G39*((B39-B38)/2)*(SIN(C38*PI()/180)*SIN(E38*PI()/180)+SIN(C39*PI()/180)*SIN(E39*PI()/180)) | R39: =SQRT(P39^2+Q39^2) | S39: =IF(AND(P39=0,Q39=0),0,IF(AND(P39>=0,Q39>=0),ATAN(Q39/P39)*(180/PI()),IF(AND(P39<0,Q39>=0),ATAN(Q39/P39)*(180/PI())+180,IF(AND(P39<0,Q39<0),ATAN(Q39/P39)*(180/PI())+180,ATAN(Q39/P39)*(180/PI())+360)))) | T39: =M39 | U39: =(-H39) | V39: =IF($V$13=1,V$15-I39,V$15+I39) | W39: =IF($W$13=1,W$15-J39,W$15+J39) | X39: =SQRT((W39-$S$186)^2+(V39-$S$186)^2)
E40: =IF($H$7="M",D40+$H$8-$H$9,IF( AND($H$7="T",$A$45="g"),D40-$H$9,IF(AND($H$7="g",$A$45="t"),D40+$H$9,D40))) | F40: =IF(C40=C39,0,ACOS(COS(C39*PI()/180)*COS(C40*PI()/180)+(SIN(C39*PI()/180)*SIN(C40*PI()/180))*COS((E40-E39)*PI()/180))*180/PI()) | G40: =IF(F40=0,1,(2/F40)*(180/PI())*TAN(F40*PI()/180/2)) | H40: =H39+(G40*((B40-B39)/2*(COS(C39*PI()/180)+COS(C40*PI()/180)))) | I40: =I39+G40*((B40-B39)/2)*(SIN(C39*PI()/180)*COS(E39*PI()/180)+SIN(C40*PI()/180)*COS(E40*PI()/180)) | J40: =J39+G40*((B40-B39)/2)*(SIN(C39*PI()/180)*SIN(E39*PI()/180)+SIN(C40*PI()/180)*SIN(E40*PI()/180)) | K40: =SQRT(I40^2+J40^2) | L40: =IF(AND(I40=0,J40=0),0,(IF(AND(I40>=0,J40>=0),ATAN(J40/I40)*(180/PI()),IF(AND(I40<0,J40>=0),ATAN(J40/I40)*(180/PI())+180,IF(AND(I40<0,J40<0),ATAN(J40/I40)*(180/PI())+180,ATAN(J40/I40)*(180/PI())+360))))) | M40: =ABS(SQRT(I40^2+J40^2)*(COS(RADIANS(($H$10-IF(I40=0,0,DEGREES(ATAN(J40/I40)))))))) | N40: =IF(B40=B39,0,F40*100/(B40-B39)) | O40: =E40+$F$7 | P40: =G40*((B40-B39)/2)*(SIN(C39*PI()/180)*COS(E39*PI()/180)+SIN(C40*PI()/180)*COS(E40*PI()/180)) | Q40: =G40*((B40-B39)/2)*(SIN(C39*PI()/180)*SIN(E39*PI()/180)+SIN(C40*PI()/180)*SIN(E40*PI()/180)) | R40: =SQRT(P40^2+Q40^2) | S40: =IF(AND(P40=0,Q40=0),0,IF(AND(P40>=0,Q40>=0),ATAN(Q40/P40)*(180/PI()),IF(AND(P40<0,Q40>=0),ATAN(Q40/P40)*(180/PI())+180,IF(AND(P40<0,Q40<0),ATAN(Q40/P40)*(180/PI())+180,ATAN(Q40/P40)*(180/PI())+360)))) | T40: =M40 | U40: =(-H40) | V40: =IF($V$13=1,V$15-I40,V$15+I40) | W40: =IF($W$13=1,W$15-J40,W$15+J40) | X40: =SQRT((W40-$S$186)^2+(V40-$S$186)^2)
E41: =IF($H$7="M",D41+$H$8-$H$9,IF( AND($H$7="T",$A$45="g"),D41-$H$9,IF(AND($H$7="g",$A$45="t"),D41+$H$9,D41))) | F41: =IF(C41=C40,0,ACOS(COS(C40*PI()/180)*COS(C41*PI()/180)+(SIN(C40*PI()/180)*SIN(C41*PI()/180))*COS((E41-E40)*PI()/180))*180/PI()) | G41: =IF(F41=0,1,(2/F41)*(180/PI())*TAN(F41*PI()/180/2)) | H41: =H40+(G41*((B41-B40)/2*(COS(C40*PI()/180)+COS(C41*PI()/180)))) | I41: =I40+G41*((B41-B40)/2)*(SIN(C40*PI()/180)*COS(E40*PI()/180)+SIN(C41*PI()/180)*COS(E41*PI()/180)) | J41: =J40+G41*((B41-B40)/2)*(SIN(C40*PI()/180)*SIN(E40*PI()/180)+SIN(C41*PI()/180)*SIN(E41*PI()/180)) | K41: =SQRT(I41^2+J41^2) | L41: =IF(AND(I41=0,J41=0),0,(IF(AND(I41>=0,J41>=0),ATAN(J41/I41)*(180/PI()),IF(AND(I41<0,J41>=0),ATAN(J41/I41)*(180/PI())+180,IF(AND(I41<0,J41<0),ATAN(J41/I41)*(180/PI())+180,ATAN(J41/I41)*(180/PI())+360))))) | M41: =ABS(SQRT(I41^2+J41^2)*(COS(RADIANS(($H$10-IF(I41=0,0,DEGREES(ATAN(J41/I41)))))))) | N41: =IF(B41=B40,0,F41*100/(B41-B40)) | O41: =E41+$F$7 | P41: =G41*((B41-B40)/2)*(SIN(C40*PI()/180)*COS(E40*PI()/180)+SIN(C41*PI()/180)*COS(E41*PI()/180)) | Q41: =G41*((B41-B40)/2)*(SIN(C40*PI()/180)*SIN(E40*PI()/180)+SIN(C41*PI()/180)*SIN(E41*PI()/180)) | R41: =SQRT(P41^2+Q41^2) | S41: =IF(AND(P41=0,Q41=0),0,IF(AND(P41>=0,Q41>=0),ATAN(Q41/P41)*(180/PI()),IF(AND(P41<0,Q41>=0),ATAN(Q41/P41)*(180/PI())+180,IF(AND(P41<0,Q41<0),ATAN(Q41/P41)*(180/PI())+180,ATAN(Q41/P41)*(180/PI())+360)))) | T41: =M41 | U41: =(-H41) | V41: =IF($V$13=1,V$15-I41,V$15+I41) | W41: =IF($W$13=1,W$15-J41,W$15+J41) | X41: =SQRT((W41-$S$186)^2+(V41-$S$186)^2)
